Workbook

Sheet 1994 E Maize VWC Introduction
A1: SHEET NAME | B1: CONTENTS
A2: 1993 E Maize VWC Introduction | B2: Authors of the data, key references to methods, symbols, conventions, explanation of sheet names and contents
A3: Dic. 1994 E Maize Profile WC | B3: Data dictionary for sheet or CSV file named "1994 E Maize Profile WC"
A4: 1994 E Maize Profile WC | B4: Summary data of soil profile water content in mm for each tube and date of neutron probe reading for the entire season.
A5: Dic. 1994 E Maize Soil VWC | B5: Data dictionary for sheet or CSV file named "1994 E Maize Soil VWC"
A6: 1994 E Maize Soil VWC | B6: Soil water content (vol/vol) for each date of reading and each depth of reading in each of 20 access tubes.
A7: Dic. 1994 E Maize Tube Map | B7: Data dictionary for sheet or CSV file named "1994 E Maize Tube Map"
A8: 1994 E Maize Tube Map | B8: Approximate mapping of neutron probe access tube locations within each field and lysimeter
A9: 1994 E Maize Graphs | B9: Graphs of the water content profile for all dates when data were taken with one graph for each neutron probe access tube. Also contain summary data of profile water content at each tube location for each date when data were taken.
A10: Data in this spreadsheet are the result of a team effort at the USDA-ARS Conservation & Production Research Laboratory, Soil and Water Management Research Unit (SWMRU).
A11: The scientists responsible for collecting these data, calibrating the instruments, quality control and data analysis are:
A12: Author | B12: Steven R. Evett, Research Soil Scientist (point of contact and responsible for this spreadsheet), Steve.Evett@usda.gov, 806-356-5775, srevett1948@gmail.com
A13: Author | B13: Paul D. Colaizzi, Research Agricultural Engineer, paul.colaizzi@usda.gov
A14: Author | B14: Karen S. Copeland, Soil Scientist, Karen.Copeland@usda.gov, 806-356-5735
A15: Author | B15: Brice B. Ruthardt, Biological Scientist, Brice.Ruthardt@usda.gov, 806-356-5780
A16: All are or were employed in the
A17: USDA-ARS Conservation & Production Research Laboratory
A18: 300 Simmons Road, Unit 10
A19: Bushland, Texas 79012 USA
A20: Persons using these data for scientific research and publication are responsible for:
A21: 1. Contacting all the scientists listed above and obtaining approval to use the data,
A22: 2. Inviting them to be involved in said research, and
A23: 3. Inviting them to be involved as coauthors in the data analysis, drafting and critical review of any publications resulting from the research.
A24: Data contained herein are from experiments in the large weighing lysimeter fields at Bushland, Texas. Neutron count measurements were taken using a model 503DR1.5 HydroProbe manufactured by Campbell Pacific Nuclear, a division of Instrotek, Inc., Concord, California. Soil horizon-specific calibrations were established at field sites using methods described by Evett (2003) and Evett et al. (2008).
A25: REFERENCES:
A26: Evett, S.R. and J.L. Steiner. 1995. Precision of neutron scattering and capacitance type soil water content gauges from field calibration. Soil Sci. Soc. Am. J. 59(4):961-968. https://doi.org/10.2136/sssaj1995.03615995005900040001x
A27: Evett, S.R. 2003a. Soil Water Measurement by Neutron Thermalization. In B.A. Stewart and Terry A. Howell (editors). Encyclopedia of Water Science, Marcel Dekker, Inc. New York. Pp. 889-893.
... A29: Evett, S.R., L.K. Heng, P. Moutonnet and M.L. Nguyen. 2008. Field Estimation of Soil Water Content: A Practical Guide to Methods, Instrumentation, and Sensor Technology. 131 pp. IAEA-TCS-30. International Atomic Energy Agency, Vienna, Austria. ISSN 1018–5518. Available at http://www-pub.iaea.org/mtcd/publications/PubDetails.asp?pubId=7801
A30: CONVENTION | B30: EXPLANATION
A31: Water content | B31: Water content data are in units of volume per unit volume of soil (m3/m3). The neutron probe was used to take readings of neutron counts at each depth in each access tube and to take standard count and Chi ratio statistics with the neutron probe locked within its shield, which was mounted on top of a depth control stand (Evett et al., 2003b). Count ratio data (count divided by long-term mean of standard counts) were converted to water content data using calibrations done in the field as described Evett and Steiner (1995) and Evett et al. (2003a, 2008). Methods for calibration and use of the neutron probe are given in the references (Evett et al., 2003a, 2008). The data have several significant digits after the decimal point but there are only approximately three significant digits after the decimal point. Accuracy of the 10-cm data were improved by use of a depth control stand and a separate calibration for that depth.
A32: Depth | B32: Depths shown are the center depths of sensing with the neutron probe
A33: Porosity | B33: Soil porosity by depth as determined from prior research that determined soil bulk density and porosity values by depth. The porosity is the air-filled pore space as a volume fraction of a unit soil volume when the soil is completely dry. Calculated from dry bulk density (BD, Mg/m3) as: Porosity = 1 - BD/2.65, where 2.65 is the particle density (Mg/m3) of quartz sand. The porosity represents a quality control limit to soil water content data. Soil water content should not be larger than porosity. Notwithstanding its use as a limit, in the case of swelling soils the water content at saturation can be somewhat larger than the porosity that is calculated from dry bulk density.
A34: SYMBOL | B34: MEANING
A35: DAP | B35: Days after planting
A36: DOY | B36: day of year. January 1 is DOY 1, February 1 is DOY 32, etc.
A37: FC | B37: Soil profile water content in mm
A38: MAD | B38: Profile water content in mm at management allowed depletion
A39: NE | B39: northeast. Refers to NE field and weighing lysimeter
A40: PWP | B40: Profile water content in mm at permanent wilting point
A41: SE | B41: southeast. Refers to SE field and weighing lysimeter
...

Sheet Dic. 1994 E Maize Profile WC
A1: Spreadsheet tab | B1: Element or value display name | C1: Description | D1: Data type | E1: Character length | F1: Acceptable values | G1: Required? | H1: Accepts null value?
A2: 1994 E Maize Profile WC | B2: Date | C2: Date in yyyy-mm-dd format | D2: date - yyyy-mm-dd | E2: 10 | G2: Yes | H2: No
A3: 1994 E Maize Profile WC | B3: DAP | C3: Days after planting | D3: integer | E3: 3 | G3: Yes | H3: No
A4: 1994 E Maize Profile WC | B4: DOY | C4: Serial day of the year beginning with 1 for January 1. | D4: integer | E4: 3 | F4: 1 to 366 | G4: Yes | H4: No
A5: 1994 E Maize Profile WC | B5: Storage in top 1.5 m of soil in SE Lys | C5: Water in mm stored in top 1.5 m of soil in SE Lys | D5: decimal | G5: Yes | H5: Yes, #N/A
A6: 1994 E Maize Profile WC | B6: Storage in top 1.5 m of soil in SE Field | C6: Water in mm stored in top 1.5 m of soil in SE Field | D6: decimal | G6: Yes | H6: Yes, #N/A
A7: 1994 E Maize Profile WC | B7: Storage in top 1.5 m of soil in NE Lys | C7: Water in mm stored in top 1.5 m of soil in NE Lys | D7: decimal | G7: Yes | H7: Yes, #N/A
A8: 1994 E Maize Profile WC | B8: Storage in top 1.5 m of soil in NE Field | C8: Water in mm stored in top 1.5 m of soil in NE Field | D8: decimal | G8: Yes | H8: Yes, #N/A
A9: 1994 E Maize Profile WC | B9: FC | C9: Water in mm stored in top 1.5 m of soil at field capacity | D9: decimal | G9: Yes | H9: Yes, #N/A
A10: 1994 E Maize Profile WC | B10: PWP | C10: Water in mm stored in top 1.5 m of soil at permanent wilting point | D10: decimal | G10: Yes | H10: Yes, #N/A
A11: 1994 E Maize Profile WC | B11: MAD | C11: Water in mm stored in top 1.5 m of soil at management allowed depletion | D11: decimal | G11: Yes | H11: Yes, #N/A
A12: 1994 E Maize Profile WC | B12: Storage in top 2.4 m of SE field tubes 1-2 | C12: Water in mm stored in top 2.4 m of SE field tubes 1-2 | D12: decimal | G12: Yes | H12: Yes, #N/A
A13: 1994 E Maize Profile WC | B13: Storage in top 2.4 m of SE field tubes 3-4 | C13: Water in mm stored in top 2.4 m of SE field tubes 3-4 | D13: decimal | G13: Yes | H13: Yes, #N/A
A14: 1994 E Maize Profile WC | B14: Storage in top 2.0 m of SE Lys tubes 5-6 | C14: Water in mm stored in top 2.0 m of SE Lys tubes 5-6 | D14: decimal | G14: Yes | H14: Yes, #N/A
A15: 1994 E Maize Profile WC | B15: Storage in top 2.4 m of NE field tubes 7-8 | C15: Water in mm stored in top 2.4 m of NE field tubes 7-8 | D15: decimal | G15: Yes | H15: Yes, #N/A
A16: 1994 E Maize Profile WC | B16: Storage in top 2.4 m of NE field tubes 9-10 | C16: Water in mm stored in top 2.4 m of NE field tubes 9-10 | D16: decimal | G16: Yes | H16: Yes, #N/A
A17: 1994 E Maize Profile WC | B17: Storage in top 2.0 m of NE Lys tubes 11-12 | C17: Water in mm stored in top 2.0 m of NE Lys tubes 11-12 | D17: decimal | G17: Yes | H17: Yes, #N/A

Sheet 1994 E Maize Profile WC
A1: Date | B1: DAP | C1: DOY | D1: Water (mm) stored in top 1.5 m of soil in SE Lys | E1: Water (mm) stored in top 1.5 m of soil in SE Field | F1: Water (mm) stored in top 1.5 m of soil in NE Lys | G1: Water (mm) stored in top 1.5 m of soil in NE Field | H1: FC | I1: PWP | J1: MAD | K1: Water stored (mm) in top 2.4 m of SE field tubes 1-2 | L1: Water stored (mm) in top 2.4 m of SE field tubes 3-4 | M1: Water stored (mm) in top 2.0 m of SE Lys tubes 5-6 | N1: Water stored (mm) in top 2.4 m of NE field tubes 7-8 | O1: Water stored (mm) in top 2.4 m of NE field tubes 9-10 | P1: Water stored (mm) in top 2.0 m of NE Lys tubes 11-12
A2: 34460 | B2: =C2-105 -> 21 | C2: 126 | D2: 341.2107 | E2: 341.56259 | F2: 414.4194 | G2: 398.97118 | H2: 495 | I2: 270 | J2: 360 | K2: 530.28689 | L2: 595.47947 | M2: 467.91934 | N2: 634.84649 | O2: 629.65778 | P2: 555.97521
A3: 34474 | B3: =C3-105 -> 35 | C3: 140 | D3: 338.79681 | E3: 341.50573 | F3: 413.33761 | G3: 400.34714 | H3: 495 | I3: 270 | J3: 360 | K3: 527.85282 | L3: 594.34656 | M3: 466.14519 | N3: 633.58345 | O3: 631.79133 | P3: 555.75739
A4: 34487 | B4: =C4-105 -> 48 | C4: 153 | D4: 337.77678 | E4: 342.13011 | F4: 412.73586 | G4: 393.95604 | H4: 495 | I4: 270 | J4: 360 | K4: 529.46835 | L4: 595.54285 | M4: 465.23332 | N4: 627.17524 | O4: 627.01399 | P4: 554.75597
A5: 34500 | B5: =C5-105 -> 61 | C5: 166 | D5: 384.9954 | E5: 367.6721 | F5: 421.47707 | G5: 403.48042 | H5: 495 | I5: 270 | J5: 360 | K5: 558.11803 | L5: 617.34533 | M5: 513.34098 | N5: 641.29262 | O5: 632.21709 | P5: 562.99463
A6: 34514 | B6: =C6-105 -> 75 | C6: 180 | D6: 381.67801 | E6: 355.8102 | F6: 430.50121 | G6: 409.67266 | H6: 495 | I6: 270 | J6: 360 | K6: 554.89743 | L6: 597.75229 | M6: 509.04485 | N6: 638.94439 | O6: 637.00533 | P6: 573.92874
A7: 34527 | B7: =C7-105 -> 88 | C7: 193 | D7: 386.27452 | E7: 416.16786 | F7: 459.66358 | G7: 446.69757 | H7: 495 | I7: 270 | J7: 360 | K7: 599.8274 | L7: 672.54834 | M7: 514.57656 | N7: 677.48939 | O7: 673.06443 | P7: 606.5668
A8: 34544 | B8: =C8-105 -> 105 | C8: 210 | D8: 392.32737 | E8: 417.72885 | F8: 458.86965 | G8: 454.81239 | H8: 495 | I8: 270 | J8: 360 | K8: 605.0106 | L8: 672.92867 | M8: 520.64656 | N8: 698.89519 | O8: 687.86447 | P8: 607.90049
A9: 34557 | B9: =C9-105 -> 118 | C9: 223 | D9: 378.82656 | E9: 408.34519 | F9: 418.13082 | G9: #N/A | H9: 495 | I9: 270 | J9: 360 | K9: 597.96282 | L9: 662.54267 | M9: 507.44122 | N9: 674.71756 | O9: 658.24466 | P9: 570.07674
A10: 34571 | B10: =C10-105 -> 132 | C10: 237 | D10: 370.79867 | E10: 404.39236 | F10: 394.44971 | G10: 395.01811 | H10: 495 | I10: 270 | J10: 360 | K10: 588.96202 | L10: 664.43585 | M10: 498.91605 | N10: 647.1313 | O10: 625.39841 | P10: 545.11616
A11: 34591 | B11: =C11-105 -> 152 | C11: 257 | D11: 384.83854 | E11: 384.80804 | F11: 413.27718 | G11: 406.73807 | H11: 495 | I11: 270 | J11: 360 | K11: 577.52862 | L11: 635.62559 | M11: 513.49145 | N11: 656.08092 | O11: 635.96191 | P11: 563.52022

Sheet Dic. 1994 E Maize Soil VWC
A1: Spreadsheet tab | B1: Element or value display name | C1: Description | D1: Data type | E1: Character length | F1: Acceptable values | G1: Required? | H1: Accepts null value?
A2: 1994 E Maize Soil VWC | B2: Year | C2: Year | D2: year - yyyy | E2: 4 | G2: Yes | H2: No
A3: 1994 E Maize Soil VWC | B3: DOY | C3: Serial day of the year beginning with 1 for January 1. | D3: integer | E3: 3 | F3: 1 to 366 | G3: Yes | H3: No
A4: 1994 E Maize Soil VWC | B4: Date | C4: Date in yyyy-mm-dd format | D4: date - year/month/day preferably ISO 8601: yyyy-mm-dd | E4: 10 | G4: Yes | H4: No
A5: 1994 E Maize Soil VWC | B5: Depth in cm | C5: Center depth in cm below the soil surface of soil water content sensing | D5: decimal | G5: Yes | H5: No
A6: 1994 E Maize Soil VWC | B6: Tube no. | C6: Number of the access tube in which the neutron probe was used to sense water content. The tube map gives the relative tube locations in the lysimeters and in the fields surrounding the lysimeters. | D6: integer | F6: 1 to 20 | G6: Yes | H6: No
A7: 1994 E Maize Soil VWC | B7: VWC | C7: Soil volumetric water content. This is a unitless fraction. | D7: decimal | F7: Zero to <1 | G7: Yes | H7: Yes, #N/A
A8: 1994 E Maize Soil VWC | B8: Location | C8: Indicates wether the access tube was in the field, indicated by Fld, or in a lysimeter, indicated by Lys, and what field it was in as indicated by the four intercardinal directions NW, SW, NE, and SE. | D8: varchar(6) | E8: 6 | H8: No

Sheet 1994 E Maize Soil VWC
A1: Year | B1: DOY | C1: Date | D1: Depth in cm | E1: Tube no. | F1: VWC | G1: Location
A2: 1994 | B2: 126 | C2: 34460 | D2: 230 | E2: 1 | F2: 0.17615554 | G2: SE Fld
A3: 1994 | B3: 126 | C3: 34460 | D3: 230 | E3: 2 | F3: 0.23551256 | G3: SE Fld
A4: 1994 | B4: 126 | C4: 34460 | D4: 230 | E4: 3 | F4: 0.23965436 | G4: SE Fld
A5: 1994 | B5: 126 | C5: 34460 | D5: 230 | E5: 4 | F5: 0.25622157 | G5: SE Fld
A6: 1994 | B6: 126 | C6: 34460 | D6: 230 | E6: 5 | F6: #N/A | G6: SE Lys
A7: 1994 | B7: 126 | C7: 34460 | D7: 230 | E7: 6 | F7: #N/A | G7: SE Lys
A8: 1994 | B8: 126 | C8: 34460 | D8: 230 | E8: 7 | F8: #N/A | G8: NW Fld
A9: 1994 | B9: 126 | C9: 34460 | D9: 230 | E9: 8 | F9: 0.25210615 | G9: NW Fld
A10: 1994 | B10: 126 | C10: 34460 | D10: 230 | E10: 9 | F10: 0.24197588 | G10: NW Fld
A11: 1994 | B11: 126 | C11: 34460 | D11: 230 | E11: 10 | F11: 0.26139222 | G11: NW Fld
A12: 1994 | B12: 126 | C12: 34460 | D12: 230 | E12: 11 | F12: #N/A | G12: NW Lys
A13: 1994 | B13: 126 | C13: 34460 | D13: 230 | E13: 12 | F13: #N/A | G13: NW Lys
A14: 1994 | B14: 126 | C14: 34460 | D14: 210 | E14: 1 | F14: 0.18610114 | G14: SE Fld
A15: 1994 | B15: 126 | C15: 34460 | D15: 210 | E15: 2 | F15: 0.25255462 | G15: SE Fld
A16: 1994 | B16: 126 | C16: 34460 | D16: 210 | E16: 3 | F16: 0.24366426 | G16: SE Fld
A17: 1994 | B17: 126 | C17: 34460 | D17: 210 | E17: 4 | F17: 0.26661564 | G17: SE Fld
A18: 1994 | B18: 126 | C18: 34460 | D18: 210 | E18: 5 | F18: #N/A | G18: SE Lys
A19: 1994 | B19: 126 | C19: 34460 | D19: 210 | E19: 6 | F19: #N/A | G19: SE Lys
A20: 1994 | B20: 126 | C20: 34460 | D20: 210 | E20: 7 | F20: #N/A | G20: NW Fld
A21: 1994 | B21: 126 | C21: 34460 | D21: 210 | E21: 8 | F21: 0.24400721 | G21: NW Fld
A22: 1994 | B22: 126 | C22: 34460 | D22: 210 | E22: 9 | F22: 0.24688273 | G22: NW Fld
A23: 1994 | B23: 126 | C23: 34460 | D23: 210 | E23: 10 | F23: 0.26811935 | G23: NW Fld
A24: 1994 | B24: 126 | C24: 34460 | D24: 210 | E24: 11 | F24: #N/A | G24: NW Lys
A25: 1994 | B25: 126 | C25: 34460 | D25: 210 | E25: 12 | F25: #N/A | G25: NW Lys
A26: 1994 | B26: 126 | C26: 34460 | D26: 190 | E26: 1 | F26: 0.21512013 | G26: SE Fld
A27: 1994 | B27: 126 | C27: 34460 | D27: 190 | E27: 2 | F27: 0.26347632 | G27: SE Fld
A28: 1994 | B28: 126 | C28: 34460 | D28: 190 | E28: 3 | F28: 0.26479536 | G28: SE Fld
A29: 1994 | B29: 126 | C29: 34460 | D29: 190 | E29: 4 | F29: 0.27009792 | G29: SE Fld
A30: 1994 | B30: 126 | C30: 34460 | D30: 190 | E30: 5 | F30: 0.23261066 | G30: SE Lys
A31: 1994 | B31: 126 | C31: 34460 | D31: 190 | E31: 6 | F31: 0.25598414 | G31: SE Lys
A32: 1994 | B32: 126 | C32: 34460 | D32: 190 | E32: 7 | F32: #N/A | G32: NW Fld
A33: 1994 | B33: 126 | C33: 34460 | D33: 190 | E33: 8 | F33: 0.25569395 | G33: NW Fld
A34: 1994 | B34: 126 | C34: 34460 | D34: 190 | E34: 9 | F34: 0.24904596 | G34: NW Fld
A35: 1994 | B35: 126 | C35: 34460 | D35: 190 | E35: 10 | F35: 0.2641886 | G35: NW Fld
A36: 1994 | B36: 126 | C36: 34460 | D36: 190 | E36: 11 | F36: 0.28492399 | G36: NW Lys
A37: 1994 | B37: 126 | C37: 34460 | D37: 190 | E37: 12 | F37: 0.28529332 | G37: NW Lys
A38: 1994 | B38: 126 | C38: 34460 | D38: 170 | E38: 1 | F38: 0.24522073 | G38: SE Fld
A39: 1994 | B39: 126 | C39: 34460 | D39: 170 | E39: 2 | F39: 0.2601787 | G39: SE Fld
A40: 1994 | B40: 126 | C40: 34460 | D40: 170 | E40: 3 | F40: 0.27732629 | G40: SE Fld
...

Sheet DIc. 1994 E Maize Tube Map
A1: Spreadsheet tab | B1: Element or value display name | C1: Description | D1: Data type | E1: Character length | F1: Acceptable values | G1: Required? | H1: Accepts null value?
A2: 1994 E Maize Tube Map | B2: Year | C2: Year in which the experiment began. | D2: yyyy | E2: 4 | G2: Yes | H2: No
A3: 1994 E Maize Tube Map | B3: Field | C3: Field in which the neutron probe access tube is located. NE for northeast, SE for southeast, NW for northwest, and SW for southwest | D3: text | E3: 2 | G3: Yes | H3: No
A4: 1994 E Maize Tube Map | B4: Span | C4: Span within which the tube was located, NE indicates the northeast field, SE indicates the southeast field. The concept of "span" is related to the 10-span, linear-move irrigation systems used to irrigate the lysimeter fields. From 1988 through 2014 a Lindsay 10-span linear move was used, and in 2015 and later a 10-span Valley system was used. Both linear-move systems were oriented with the lateral pipe in the north-south direction, and therefore irrigated moving in the east-west direction. In 2012 the NE and SE fields were converted to drip irrigation, but the sampling was still done in areas consistent with the dimensions previously used under the linear-move system. Spans were numbered consecutively 1 through 10 beginning on the north end and ending on the south end. Measured from the north end of the linear-move system, span beginning and ending distances for the Lindsay system were: Span 1, 0 to 23.93 m; Span 2, 23.93 to 71.78 m; Span 3, 71.78 m to 112.93 m; Span 4, 112.93 m to 154.08 m; Span 5, 154.08 m to 201.93 m; Span 6, 201.93 m to 249.02 m; Span 7, 249.02 m to 296.111 m; Span 8, 296.11 m to 337.26 m; Span 9, 337.26 m to 378. 41 m; Span 10, 378.41 m to 422.92 m. An overhang pipe south of span 10 was used to irrigate a few rows on the extreme southern edge of the fields. In typical usage in these data sheets, the word span and the span number indicate only relative position of sampling from north to south in a field. However, when yield per unit area was calculated, the actual yield within a span and the north-south dimension of the yield sample area were used in the calculation along with an east-west dimension of the cropped and sampled area. | D4: integer | G4: Yes | H4: No
A5: 1994 E Maize Tube Map | B5: Tube number | C5: Number assigned to a particular neutron probe access tube. | D5: integer | G5: Yes | H5: No
A6: 1994 E Maize Tube Map | B6: Relative position | C6: Position of the access tube relative to the lysimeter. There is a lysimeter centered in the NE field and a lysimeter centered in the SE field. Positions are NE for northeast of the lysimeter, NW for northwest of the lysimeter, SW for southwest of the lysimeter, and SE for southeast of the lysimeter. Access tubes in the lysimeter soil monolith were either in the southwest quadrant designated by LYS-SW or the northeast quadrant designated by LYS-NE. Access tubes outside a lysimeter were approximately 20- to 50-meters from the lysimeter. | D6: text | E6: variable | G6: Yes | H6: No
A7: 1994 E Maize Tube Map | B7: Latitude | C7: Latitude in decimal degrees (based on approximate distances from lysimeter center) | D7: decimal | G7: Yes | H7: No
A8: 1994 E Maize Tube Map | B8: Longitude | C8: Longitude in decimal degrees (based on approximate distances from lysimeter center) | D8: decimal | G8: Yes | H8: No

Sheet 1994 E Maize Tube Map
A1: Year | B1: Field | C1: Span | D1: Tube number | E1: Relative position | F1: latitude | G1: longitude
A2: 1994 | B2: SE | C2: 8 | D2: 1 | E2: NE | F2: 35.186248 | G2: -102.09541
A3: 1994 | B3: SE | C3: 8 | D3: 2 | E3: NW | F3: 35.186248 | G3: -102.0957
A4: 1994 | B4: SE | C4: 8 | D4: 3 | E4: SW | F4: 35.186032 | G4: -102.0957
A5: 1994 | B5: SE | C5: 8 | D5: 4 | E5: SE | F5: 35.186032 | G5: -102.09541
A6: 1994 | B6: SE | C6: 8 | D6: 5 | E6: LYS-SE | F6: 35.186144 | G6: -102.09554
A7: 1994 | B7: SE | C7: 8 | D7: 6 | E7: LYS-NE | F7: 35.186137 | G7: -102.09556
A8: 1994 | B8: NE | C8: 3 | D8: 7 | E8: NE | F8: 35.188278 | G8: -102.0954
A9: 1994 | B9: NE | C9: 3 | D9: 8 | E9: NW | F9: 35.188278 | G9: -102.09569
A10: 1994 | B10: NE | C10: 3 | D10: 9 | E10: SW | F10: 35.188062 | G10: -102.09569
A11: 1994 | B11: NE | C11: 3 | D11: 10 | E11: SE | F11: 35.188062 | G11: -102.0954
A12: 1994 | B12: NE | C12: 3 | D12: 11 | E12: LYS-SW | F12: 35.188173 | G12: -102.09553
A13: 1994 | B13: NE | C13: 3 | D13: 12 | E13: LYS-NE | F13: 35.188166 | G13: -102.09555

Sheet 1994 E Maize Graphs
Y1: Depth (cm) | Z1: 230 | AA1: 210 | AB1: 190 | AC1: 170 | AD1: 150 | AE1: 130 | AF1: 110 | AG1: 90 | AH1: 70 | AI1: 50 | AJ1: 30 | AK1: 10 | AO1: DOY | AP1: Date | AQ1: Water (mm) stored in top 1.5 m of soil in SE Lys | AR1: Water (mm) stored in top 1.5 m of soil in SE Field | AS1: Water (mm) stored in top 1.5 m of soil in NE Lys | AT1: Water (mm) stored in top 1.5 m of soil in NE Field | AU1: DOY | AV1: Water stored (mm) in top 2.4 m of SE field tubes 1-2 | AW1: Water stored (mm) in top 2.4 m of SE field tubes 3-4 | AX1: Water stored (mm) in top 2.0 m of SE Lys tubes 5-6 | AY1: Water stored (mm) in top 2.4 m of NE field tubes 7-8 | AZ1: Water stored (mm) in top 2.4 m of NE field tubes 9-10 | BA1: Water stored (mm) in top 2.0 m of NE Lys tubes 11-12
Y2: Porosity (m3/m3) | AA2: 0.46977987 | AB2: 0.4691195 | AC2: 0.45975262 | AD2: 0.46509434 | AE2: 0.42485115 | AF2: 0.41714735 | AG2: 0.44435759 | AH2: 0.45478559 | AI2: 0.43505765 | AJ2: 0.45794811 | AK2: 0.48951842
AC3: VWC | AD3: VWC | AE3: VWC | AF3: VWC | AG3: VWC | AH3: VWC | AI3: VWC | AJ3: VWC | AK3: VWC | AL3: VWC | AM3: VWC | AN3: VWC
AC4: tube no. | AD4: tube no. | AE4: tube no. | AF4: tube no. | AG4: tube no. | AH4: tube no. | AI4: tube no. | AJ4: tube no. | AK4: tube no. | AL4: tube no. | AM4: tube no. | AN4: tube no.
Y5: Year | Z5: DOY | AA5: Date | AB5: Depth | AC5: 1 | AD5: 2 | AE5: 3 | AF5: 4 | AG5: 5 | AH5: 6 | AI5: 7 | AJ5: 8 | AK5: 9 | AL5: 10 | AM5: 11 | AN5: 12
Y6: 1994 | Z6: 126 | AA6: =DATE(Y6,1,Z6) -> 34460 | AB6: 10 | AC6: {=_xlfn.XLOOKUP(1,('1994 E Maize Soil VWC'!$C$2:$C$4000=$AA6)*('1994 E Maize Soil VWC'!$D$2:$D$4000=$AB6)*('1994 E Maize Soil VWC'!$E$2:$E$4000=AC$5),'1994 E Maize Soil VWC'!$F$2:$F$4000)} -> 0.24731393 | AD6: {=_xlfn.XLOOKUP(1,('1994 E Maize Soil VWC'!$C$2:$C$4000=$AA6)*('1994 E Maize Soil VWC'!$D$2:$D$4000=$AB6)*('1994 E Maize Soil VWC'!$E$2:$E$4000=AD$5),'1994 E Maize Soil VWC'!$F$2:$F$4000)} -> 0.23666221 | AE6: {=_xlfn.XLOOKUP(1,('1994 E Maize Soil VWC'!$C$2:$C$4000=$AA6)*('1994 E Maize Soil VWC'!$D$2:$D$4000=$AB6)*('1994 E Maize Soil VWC'!$E$2:$E$4000=AE$5),'1994 E Maize Soil VWC'!$F$2:$F$4000)} -> 0.25368241 | AF6: {=_xlfn.XLOOKUP(1,('1994 E Maize Soil VWC'!$C$2:$C$4000=$AA6)*('1994 E Maize Soil VWC'!$D$2:$D$4000=$AB6)*('1994 E Maize Soil VWC'!$E$2:$E$4000=AF$5),'1994 E Maize Soil VWC'!$F$2:$F$4000)} -> 0.25058271 | AG6: {=_xlfn.XLOOKUP(1,('1994 E Maize Soil VWC'!$C$2:$C$4000=$AA6)*('1994 E Maize Soil VWC'!$D$2:$D$4000=$AB6)*('1994 E Maize Soil VWC'!$E$2:$E$4000=AG$5),'1994 E Maize Soil VWC'!$F$2:$F$4000)} -> 0.23660585 | AH6: {=_xlfn.XLOOKUP(1,('1994 E Maize Soil VWC'!$C$2:$C$4000=$AA6)*('1994 E Maize Soil VWC'!$D$2:$D$4000=$AB6)*('1994 E Maize Soil VWC'!$E$2:$E$4000=AH$5),'1994 E Maize Soil VWC'!$F$2:$F$4000)} -> 0.22130458 | AI6: {=_xlfn.XLOOKUP(1,('1994 E Maize Soil VWC'!$C$2:$C$4000=$AA6)*('1994 E Maize Soil VWC'!$D$2:$D$4000=$AB6)*('1994 E Maize Soil VWC'!$E$2:$E$4000=AI$5),'1994 E Maize Soil VWC'!$F$2:$F$4000)} -> #N/A | AJ6: {=_xlfn.XLOOKUP(1,('1994 E Maize Soil VWC'!$C$2:$C$4000=$AA6)*('1994 E Maize Soil VWC'!$D$2:$D$4000=$AB6)*('1994 E Maize Soil VWC'!$E$2:$E$4000=AJ$5),'1994 E Maize Soil VWC'!$F$2:$F$4000)} -> 0.27264697 | ... AN6: {=_xlfn.XLOOKUP(1,('1994 E Maize Soil VWC'!$C$2:$C$4000=$AA6)*('1994 E Maize Soil VWC'!$D$2:$D$4000=$AB6)*('1994 E Maize Soil VWC'!$E$2:$E$4000=AN$5),'1994 E Maize Soil VWC'!$F$2:$F$4000)} -> 0.25551406 | AO6: =Z6 -> 126 | AP6: =AA6 -> 34460 | AQ6: =AVERAGE(AG6:AH12)*1400+AVERAGE(AG13:AH13)*100 -> 341.2107 | AR6: =AVERAGE(AC6:AF12)*1400+AVERAGE(AC13:AF13)*100 -> 341.56259 | AS6: =AVERAGE(AM6:AN12)*1400+AVERAGE(AM13:AN13)*100 -> 414.4194 | AT6: =AVERAGE(AJ6:AL12)*1400+AVERAGE(AJ13:AL13)*100 -> 398.97118 | AU6: =Z6 -> 126 | AV6: =AVERAGE(AC6:AD17)*2400 -> 530.28689 | AW6: =AVERAGE(AE6:AF17)*2400 -> 595.47947 | AX6: =AVERAGE(AG6:AH15)*2000 -> 467.91934 | AY6: =AVERAGE(AJ6:AJ17)*2400 -> 634.84649 | AZ6: =AVERAGE(AK6:AL17)*2400 -> 629.65778 | BA6: =AVERAGE(AM6:AN15)*2000 -> 555.97521
AA7: =AA6 -> 34460 | AB7: =AB6+20 -> 30 | AC7: {=_xlfn.XLOOKUP(1,('1994 E Maize Soil VWC'!$C$2:$C$4000=$AA7)*('1994 E Maize Soil VWC'!$D$2:$D$4000=$AB7)*('1994 E Maize Soil VWC'!$E$2:$E$4000=AC$5),'1994 E Maize Soil VWC'!$F$2:$F$4000)} -> 0.20874104 | AD7: {=_xlfn.XLOOKUP(1,('1994 E Maize Soil VWC'!$C$2:$C$4000=$AA7)*('1994 E Maize Soil VWC'!$D$2:$D$4000=$AB7)*('1994 E Maize Soil VWC'!$E$2:$E$4000=AD$5),'1994 E Maize Soil VWC'!$F$2:$F$4000)} -> 0.17707223 | AE7: {=_xlfn.XLOOKUP(1,('1994 E Maize Soil VWC'!$C$2:$C$4000=$AA7)*('1994 E Maize Soil VWC'!$D$2:$D$4000=$AB7)*('1994 E Maize Soil VWC'!$E$2:$E$4000=AE$5),'1994 E Maize Soil VWC'!$F$2:$F$4000)} -> 0.24959154 | AF7: {=_xlfn.XLOOKUP(1,('1994 E Maize Soil VWC'!$C$2:$C$4000=$AA7)*('1994 E Maize Soil VWC'!$D$2:$D$4000=$AB7)*('1994 E Maize Soil VWC'!$E$2:$E$4000=AF$5),'1994 E Maize Soil VWC'!$F$2:$F$4000)} -> 0.2541985 | AG7: {=_xlfn.XLOOKUP(1,('1994 E Maize Soil VWC'!$C$2:$C$4000=$AA7)*('1994 E Maize Soil VWC'!$D$2:$D$4000=$AB7)*('1994 E Maize Soil VWC'!$E$2:$E$4000=AG$5),'1994 E Maize Soil VWC'!$F$2:$F$4000)} -> 0.30416627 | AH7: {=_xlfn.XLOOKUP(1,('1994 E Maize Soil VWC'!$C$2:$C$4000=$AA7)*('1994 E Maize Soil VWC'!$D$2:$D$4000=$AB7)*('1994 E Maize Soil VWC'!$E$2:$E$4000=AH$5),'1994 E Maize Soil VWC'!$F$2:$F$4000)} -> 0.22095108 | AI7: {=_xlfn.XLOOKUP(1,('1994 E Maize Soil VWC'!$C$2:$C$4000=$AA7)*('1994 E Maize Soil VWC'!$D$2:$D$4000=$AB7)*('1994 E Maize Soil VWC'!$E$2:$E$4000=AI$5),'1994 E Maize Soil VWC'!$F$2:$F$4000)} -> #N/A | AJ7: {=_xlfn.XLOOKUP(1,('1994 E Maize Soil VWC'!$C$2:$C$4000=$AA7)*('1994 E Maize Soil VWC'!$D$2:$D$4000=$AB7)*('1994 E Maize Soil VWC'!$E$2:$E$4000=AJ$5),'1994 E Maize Soil VWC'!$F$2:$F$4000)} -> 0.25903097 | ... AN7: {=_xlfn.XLOOKUP(1,('1994 E Maize Soil VWC'!$C$2:$C$4000=$AA7)*('1994 E Maize Soil VWC'!$D$2:$D$4000=$AB7)*('1994 E Maize Soil VWC'!$E$2:$E$4000=AN$5),'1994 E Maize Soil VWC'!$F$2:$F$4000)} -> 0.29231061 | AO7: =Z19 -> 140 | AP7: =AA19 -> 34474 | AQ7: =AVERAGE(AG19:AH25)*1400+AVERAGE(AG26:AH26)*100 -> 338.79681 | AR7: =AVERAGE(AC19:AF25)*1400+AVERAGE(AC26:AF26)*100 -> 341.50573 | AS7: =AVERAGE(AM19:AN25)*1400+AVERAGE(AM26:AN26)*100 -> 413.33761 | AT7: =AVERAGE(AJ19:AL25)*1400+AVERAGE(AJ26:AL26)*100 -> 400.34714 | AU7: =Z19 -> 140 | AV7: =AVERAGE(AC19:AD30)*2400 -> 527.85282 | AW7: =AVERAGE(AE19:AF30)*2400 -> 594.34656 | AX7: =AVERAGE(AG19:AH28)*2000 -> 466.14519 | AY7: =AVERAGE(AJ19:AJ30)*2400 -> 633.58345 | AZ7: =AVERAGE(AK19:AL30)*2400 -> 631.79133 | BA7: =AVERAGE(AM19:AN28)*2000 -> 555.75739
AA8: =AA7 -> 34460 | AB8: =AB7+20 -> 50 | AC8: {=_xlfn.XLOOKUP(1,('1994 E Maize Soil VWC'!$C$2:$C$4000=$AA8)*('1994 E Maize Soil VWC'!$D$2:$D$4000=$AB8)*('1994 E Maize Soil VWC'!$E$2:$E$4000=AC$5),'1994 E Maize Soil VWC'!$F$2:$F$4000)} -> 0.21183382 | AD8: {=_xlfn.XLOOKUP(1,('1994 E Maize Soil VWC'!$C$2:$C$4000=$AA8)*('1994 E Maize Soil VWC'!$D$2:$D$4000=$AB8)*('1994 E Maize Soil VWC'!$E$2:$E$4000=AD$5),'1994 E Maize Soil VWC'!$F$2:$F$4000)} -> 0.21821268 | AE8: {=_xlfn.XLOOKUP(1,('1994 E Maize Soil VWC'!$C$2:$C$4000=$AA8)*('1994 E Maize Soil VWC'!$D$2:$D$4000=$AB8)*('1994 E Maize Soil VWC'!$E$2:$E$4000=AE$5),'1994 E Maize Soil VWC'!$F$2:$F$4000)} -> 0.24218175 | AF8: {=_xlfn.XLOOKUP(1,('1994 E Maize Soil VWC'!$C$2:$C$4000=$AA8)*('1994 E Maize Soil VWC'!$D$2:$D$4000=$AB8)*('1994 E Maize Soil VWC'!$E$2:$E$4000=AF$5),'1994 E Maize Soil VWC'!$F$2:$F$4000)} -> 0.24211732 | AG8: {=_xlfn.XLOOKUP(1,('1994 E Maize Soil VWC'!$C$2:$C$4000=$AA8)*('1994 E Maize Soil VWC'!$D$2:$D$4000=$AB8)*('1994 E Maize Soil VWC'!$E$2:$E$4000=AG$5),'1994 E Maize Soil VWC'!$F$2:$F$4000)} -> 0.25461731 | AH8: {=_xlfn.XLOOKUP(1,('1994 E Maize Soil VWC'!$C$2:$C$4000=$AA8)*('1994 E Maize Soil VWC'!$D$2:$D$4000=$AB8)*('1994 E Maize Soil VWC'!$E$2:$E$4000=AH$5),'1994 E Maize Soil VWC'!$F$2:$F$4000)} -> 0.21260701 | AI8: {=_xlfn.XLOOKUP(1,('1994 E Maize Soil VWC'!$C$2:$C$4000=$AA8)*('1994 E Maize Soil VWC'!$D$2:$D$4000=$AB8)*('1994 E Maize Soil VWC'!$E$2:$E$4000=AI$5),'1994 E Maize Soil VWC'!$F$2:$F$4000)} -> #N/A | AJ8: {=_xlfn.XLOOKUP(1,('1994 E Maize Soil VWC'!$C$2:$C$4000=$AA8)*('1994 E Maize Soil VWC'!$D$2:$D$4000=$AB8)*('1994 E Maize Soil VWC'!$E$2:$E$4000=AJ$5),'1994 E Maize Soil VWC'!$F$2:$F$4000)} -> 0.26795494 | ... AN8: {=_xlfn.XLOOKUP(1,('1994 E Maize Soil VWC'!$C$2:$C$4000=$AA8)*('1994 E Maize Soil VWC'!$D$2:$D$4000=$AB8)*('1994 E Maize Soil VWC'!$E$2:$E$4000=AN$5),'1994 E Maize Soil VWC'!$F$2:$F$4000)} -> 0.26402453 | AO8: =Z32 -> 153 | AP8: =AA32 -> 34487 | AQ8: =AVERAGE(AG32:AH38)*1400+AVERAGE(AG39:AH39)*100 -> 337.77678 | AR8: =AVERAGE(AC32:AF38)*1400+AVERAGE(AC39:AF39)*100 -> 342.13011 | AS8: =AVERAGE(AM32:AN38)*1400+AVERAGE(AM39:AN39)*100 -> 412.73586 | AT8: =AVERAGE(AI32:AL38)*1400+AVERAGE(AI39:AL39)*100 -> 393.95604 | AU8: =Z32 -> 153 | AV8: =AVERAGE(AC32:AD43)*2400 -> 529.46835 | AW8: =AVERAGE(AE32:AF43)*2400 -> 595.54285 | AX8: =AVERAGE(AG32:AH41)*2000 -> 465.23332 | AY8: =AVERAGE(AI32:AJ43)*2400 -> 627.17524 | AZ8: =AVERAGE(AK32:AL43)*2400 -> 627.01399 | BA8: =AVERAGE(AM32:AN41)*2000 -> 554.75597
AA9: =AA8 -> 34460 | AB9: =AB8+20 -> 70 | AC9: {=_xlfn.XLOOKUP(1,('1994 E Maize Soil VWC'!$C$2:$C$4000=$AA9)*('1994 E Maize Soil VWC'!$D$2:$D$4000=$AB9)*('1994 E Maize Soil VWC'!$E$2:$E$4000=AC$5),'1994 E Maize Soil VWC'!$F$2:$F$4000)} -> 0.20835444 | AD9: {=_xlfn.XLOOKUP(1,('1994 E Maize Soil VWC'!$C$2:$C$4000=$AA9)*('1994 E Maize Soil VWC'!$D$2:$D$4000=$AB9)*('1994 E Maize Soil VWC'!$E$2:$E$4000=AD$5),'1994 E Maize Soil VWC'!$F$2:$F$4000)} -> 0.20510057 | AE9: {=_xlfn.XLOOKUP(1,('1994 E Maize Soil VWC'!$C$2:$C$4000=$AA9)*('1994 E Maize Soil VWC'!$D$2:$D$4000=$AB9)*('1994 E Maize Soil VWC'!$E$2:$E$4000=AE$5),'1994 E Maize Soil VWC'!$F$2:$F$4000)} -> 0.22272299 | AF9: {=_xlfn.XLOOKUP(1,('1994 E Maize Soil VWC'!$C$2:$C$4000=$AA9)*('1994 E Maize Soil VWC'!$D$2:$D$4000=$AB9)*('1994 E Maize Soil VWC'!$E$2:$E$4000=AF$5),'1994 E Maize Soil VWC'!$F$2:$F$4000)} -> 0.19601552 | AG9: {=_xlfn.XLOOKUP(1,('1994 E Maize Soil VWC'!$C$2:$C$4000=$AA9)*('1994 E Maize Soil VWC'!$D$2:$D$4000=$AB9)*('1994 E Maize Soil VWC'!$E$2:$E$4000=AG$5),'1994 E Maize Soil VWC'!$F$2:$F$4000)} -> 0.20406964 | AH9: {=_xlfn.XLOOKUP(1,('1994 E Maize Soil VWC'!$C$2:$C$4000=$AA9)*('1994 E Maize Soil VWC'!$D$2:$D$4000=$AB9)*('1994 E Maize Soil VWC'!$E$2:$E$4000=AH$5),'1994 E Maize Soil VWC'!$F$2:$F$4000)} -> 0.20432738 | AI9: {=_xlfn.XLOOKUP(1,('1994 E Maize Soil VWC'!$C$2:$C$4000=$AA9)*('1994 E Maize Soil VWC'!$D$2:$D$4000=$AB9)*('1994 E Maize Soil VWC'!$E$2:$E$4000=AI$5),'1994 E Maize Soil VWC'!$F$2:$F$4000)} -> #N/A | AJ9: {=_xlfn.XLOOKUP(1,('1994 E Maize Soil VWC'!$C$2:$C$4000=$AA9)*('1994 E Maize Soil VWC'!$D$2:$D$4000=$AB9)*('1994 E Maize Soil VWC'!$E$2:$E$4000=AJ$5),'1994 E Maize Soil VWC'!$F$2:$F$4000)} -> 0.27033896 | ... AN9: {=_xlfn.XLOOKUP(1,('1994 E Maize Soil VWC'!$C$2:$C$4000=$AA9)*('1994 E Maize Soil VWC'!$D$2:$D$4000=$AB9)*('1994 E Maize Soil VWC'!$E$2:$E$4000=AN$5),'1994 E Maize Soil VWC'!$F$2:$F$4000)} -> 0.26988793 | AO9: =Z45 -> 166 | AP9: =AA45 -> 34500 | AQ9: =AVERAGE(AG45:AH51)*1400+AVERAGE(AG52:AH52)*100 -> 384.9954 | AR9: =AVERAGE(AC45:AF51)*1400+AVERAGE(AC52:AF52)*100 -> 367.6721 | AS9: =AVERAGE(AM45:AN51)*1400+AVERAGE(AM52:AN52)*100 -> 421.47707 | AT9: =AVERAGE(AI45:AL51)*1400+AVERAGE(AI52:AL52)*100 -> 403.48042 | AU9: =Z45 -> 166 | AV9: =AVERAGE(AC45:AD56)*2400 -> 558.11803 | AW9: =AVERAGE(AE45:AF56)*2400 -> 617.34533 | AX9: =AVERAGE(AG45:AH54)*2000 -> 513.34098 | AY9: =AVERAGE(AI45:AJ56)*2400 -> 641.29262 | AZ9: =AVERAGE(AK45:AL56)*2400 -> 632.21709 | BA9: =AVERAGE(AM45:AN54)*2000 -> 562.99463
AA10: =AA9 -> 34460 | AB10: =AB9+20 -> 90 | AC10: {=_xlfn.XLOOKUP(1,('1994 E Maize Soil VWC'!$C$2:$C$4000=$AA10)*('1994 E Maize Soil VWC'!$D$2:$D$4000=$AB10)*('1994 E Maize Soil VWC'!$E$2:$E$4000=AC$5),'1994 E Maize Soil VWC'!$F$2:$F$4000)} -> 0.21338021 | AD10: {=_xlfn.XLOOKUP(1,('1994 E Maize Soil VWC'!$C$2:$C$4000=$AA10)*('1994 E Maize Soil VWC'!$D$2:$D$4000=$AB10)*('1994 E Maize Soil VWC'!$E$2:$E$4000=AD$5),'1994 E Maize Soil VWC'!$F$2:$F$4000)} -> 0.19978485 | AE10: {=_xlfn.XLOOKUP(1,('1994 E Maize Soil VWC'!$C$2:$C$4000=$AA10)*('1994 E Maize Soil VWC'!$D$2:$D$4000=$AB10)*('1994 E Maize Soil VWC'!$E$2:$E$4000=AE$5),'1994 E Maize Soil VWC'!$F$2:$F$4000)} -> 0.21776165 | AF10: {=_xlfn.XLOOKUP(1,('1994 E Maize Soil VWC'!$C$2:$C$4000=$AA10)*('1994 E Maize Soil VWC'!$D$2:$D$4000=$AB10)*('1994 E Maize Soil VWC'!$E$2:$E$4000=AF$5),'1994 E Maize Soil VWC'!$F$2:$F$4000)} -> 0.20532609 | AG10: {=_xlfn.XLOOKUP(1,('1994 E Maize Soil VWC'!$C$2:$C$4000=$AA10)*('1994 E Maize Soil VWC'!$D$2:$D$4000=$AB10)*('1994 E Maize Soil VWC'!$E$2:$E$4000=AG$5),'1994 E Maize Soil VWC'!$F$2:$F$4000)} -> 0.19614439 | AH10: {=_xlfn.XLOOKUP(1,('1994 E Maize Soil VWC'!$C$2:$C$4000=$AA10)*('1994 E Maize Soil VWC'!$D$2:$D$4000=$AB10)*('1994 E Maize Soil VWC'!$E$2:$E$4000=AH$5),'1994 E Maize Soil VWC'!$F$2:$F$4000)} -> 0.20348975 | AI10: {=_xlfn.XLOOKUP(1,('1994 E Maize Soil VWC'!$C$2:$C$4000=$AA10)*('1994 E Maize Soil VWC'!$D$2:$D$4000=$AB10)*('1994 E Maize Soil VWC'!$E$2:$E$4000=AI$5),'1994 E Maize Soil VWC'!$F$2:$F$4000)} -> #N/A | AJ10: {=_xlfn.XLOOKUP(1,('1994 E Maize Soil VWC'!$C$2:$C$4000=$AA10)*('1994 E Maize Soil VWC'!$D$2:$D$4000=$AB10)*('1994 E Maize Soil VWC'!$E$2:$E$4000=AJ$5),'1994 E Maize Soil VWC'!$F$2:$F$4000)} -> 0.27043561 | ... AN10: {=_xlfn.XLOOKUP(1,('1994 E Maize Soil VWC'!$C$2:$C$4000=$AA10)*('1994 E Maize Soil VWC'!$D$2:$D$4000=$AB10)*('1994 E Maize Soil VWC'!$E$2:$E$4000=AN$5),'1994 E Maize Soil VWC'!$F$2:$F$4000)} -> 0.27819978 | AO10: =Z58 -> 180 | AP10: =AA58 -> 34514 | AQ10: =AVERAGE(AG58:AH64)*1400+AVERAGE(AG65:AH65)*100 -> 381.67801 | AR10: =AVERAGE(AC58:AF64)*1400+AVERAGE(AC65:AF65)*100 -> 355.8102 | AS10: =AVERAGE(AM58:AN64)*1400+AVERAGE(AM65:AN65)*100 -> 430.50121 | AT10: =AVERAGE(AJ58:AL64)*1400+AVERAGE(AJ65:AL65)*100 -> 409.67266 | AU10: =Z58 -> 180 | AV10: =AVERAGE(AC58:AD69)*2400 -> 554.89743 | AW10: =AVERAGE(AE58:AF69)*2400 -> 597.75229 | AX10: =AVERAGE(AG58:AH67)*2000 -> 509.04485 | AY10: =AVERAGE(AI58:AJ69)*2400 -> 638.94439 | AZ10: =AVERAGE(AK58:AL69)*2400 -> 637.00533 | BA10: =AVERAGE(AM58:AN67)*2000 -> 573.92874
AA11: =AA10 -> 34460 | AB11: =AB10+20 -> 110 | AC11: {=_xlfn.XLOOKUP(1,('1994 E Maize Soil VWC'!$C$2:$C$4000=$AA11)*('1994 E Maize Soil VWC'!$D$2:$D$4000=$AB11)*('1994 E Maize Soil VWC'!$E$2:$E$4000=AC$5),'1994 E Maize Soil VWC'!$F$2:$F$4000)} -> 0.22974619 | AD11: {=_xlfn.XLOOKUP(1,('1994 E Maize Soil VWC'!$C$2:$C$4000=$AA11)*('1994 E Maize Soil VWC'!$D$2:$D$4000=$AB11)*('1994 E Maize Soil VWC'!$E$2:$E$4000=AD$5),'1994 E Maize Soil VWC'!$F$2:$F$4000)} -> 0.21044851 | AE11: {=_xlfn.XLOOKUP(1,('1994 E Maize Soil VWC'!$C$2:$C$4000=$AA11)*('1994 E Maize Soil VWC'!$D$2:$D$4000=$AB11)*('1994 E Maize Soil VWC'!$E$2:$E$4000=AE$5),'1994 E Maize Soil VWC'!$F$2:$F$4000)} -> 0.23213021 | AF11: {=_xlfn.XLOOKUP(1,('1994 E Maize Soil VWC'!$C$2:$C$4000=$AA11)*('1994 E Maize Soil VWC'!$D$2:$D$4000=$AB11)*('1994 E Maize Soil VWC'!$E$2:$E$4000=AF$5),'1994 E Maize Soil VWC'!$F$2:$F$4000)} -> 0.24359928 | AG11: {=_xlfn.XLOOKUP(1,('1994 E Maize Soil VWC'!$C$2:$C$4000=$AA11)*('1994 E Maize Soil VWC'!$D$2:$D$4000=$AB11)*('1994 E Maize Soil VWC'!$E$2:$E$4000=AG$5),'1994 E Maize Soil VWC'!$F$2:$F$4000)} -> 0.22294851 | AH11: {=_xlfn.XLOOKUP(1,('1994 E Maize Soil VWC'!$C$2:$C$4000=$AA11)*('1994 E Maize Soil VWC'!$D$2:$D$4000=$AB11)*('1994 E Maize Soil VWC'!$E$2:$E$4000=AH$5),'1994 E Maize Soil VWC'!$F$2:$F$4000)} -> 0.22165985 | AI11: {=_xlfn.XLOOKUP(1,('1994 E Maize Soil VWC'!$C$2:$C$4000=$AA11)*('1994 E Maize Soil VWC'!$D$2:$D$4000=$AB11)*('1994 E Maize Soil VWC'!$E$2:$E$4000=AI$5),'1994 E Maize Soil VWC'!$F$2:$F$4000)} -> #N/A | AJ11: {=_xlfn.XLOOKUP(1,('1994 E Maize Soil VWC'!$C$2:$C$4000=$AA11)*('1994 E Maize Soil VWC'!$D$2:$D$4000=$AB11)*('1994 E Maize Soil VWC'!$E$2:$E$4000=AJ$5),'1994 E Maize Soil VWC'!$F$2:$F$4000)} -> 0.27565468 | ... AN11: {=_xlfn.XLOOKUP(1,('1994 E Maize Soil VWC'!$C$2:$C$4000=$AA11)*('1994 E Maize Soil VWC'!$D$2:$D$4000=$AB11)*('1994 E Maize Soil VWC'!$E$2:$E$4000=AN$5),'1994 E Maize Soil VWC'!$F$2:$F$4000)} -> 0.28216241 | AO11: =Z71 -> 193 | AP11: =AA71 -> 34527 | AQ11: =AVERAGE(AG71:AH77)*1400+AVERAGE(AG78:AH78)*100 -> 386.27452 | AR11: =AVERAGE(AC71:AF77)*1400+AVERAGE(AC78:AF78)*100 -> 416.16786 | AS11: =AVERAGE(AM71:AN77)*1400+AVERAGE(AM78:AN78)*100 -> 459.66358 | AT11: =AVERAGE(AJ71:AL77)*1400+AVERAGE(AJ78:AL78)*100 -> 446.69757 | AU11: =Z71 -> 193 | AV11: =AVERAGE(AC71:AD82)*2400 -> 599.8274 | AW11: =AVERAGE(AE71:AF82)*2400 -> 672.54834 | AX11: =AVERAGE(AG71:AH80)*2000 -> 514.57656 | AY11: =AVERAGE(AI71:AJ82)*2400 -> 677.48939 | AZ11: =AVERAGE(AK71:AL82)*2400 -> 673.06443 | BA11: =AVERAGE(AM71:AN80)*2000 -> 606.5668
AA12: =AA11 -> 34460 | AB12: =AB11+20 -> 130 | AC12: {=_xlfn.XLOOKUP(1,('1994 E Maize Soil VWC'!$C$2:$C$4000=$AA12)*('1994 E Maize Soil VWC'!$D$2:$D$4000=$AB12)*('1994 E Maize Soil VWC'!$E$2:$E$4000=AC$5),'1994 E Maize Soil VWC'!$F$2:$F$4000)} -> 0.24450845 | AD12: {=_xlfn.XLOOKUP(1,('1994 E Maize Soil VWC'!$C$2:$C$4000=$AA12)*('1994 E Maize Soil VWC'!$D$2:$D$4000=$AB12)*('1994 E Maize Soil VWC'!$E$2:$E$4000=AD$5),'1994 E Maize Soil VWC'!$F$2:$F$4000)} -> 0.21047709 | AE12: {=_xlfn.XLOOKUP(1,('1994 E Maize Soil VWC'!$C$2:$C$4000=$AA12)*('1994 E Maize Soil VWC'!$D$2:$D$4000=$AB12)*('1994 E Maize Soil VWC'!$E$2:$E$4000=AE$5),'1994 E Maize Soil VWC'!$F$2:$F$4000)} -> 0.25281843 | AF12: {=_xlfn.XLOOKUP(1,('1994 E Maize Soil VWC'!$C$2:$C$4000=$AA12)*('1994 E Maize Soil VWC'!$D$2:$D$4000=$AB12)*('1994 E Maize Soil VWC'!$E$2:$E$4000=AF$5),'1994 E Maize Soil VWC'!$F$2:$F$4000)} -> 0.24537902 | AG12: {=_xlfn.XLOOKUP(1,('1994 E Maize Soil VWC'!$C$2:$C$4000=$AA12)*('1994 E Maize Soil VWC'!$D$2:$D$4000=$AB12)*('1994 E Maize Soil VWC'!$E$2:$E$4000=AG$5),'1994 E Maize Soil VWC'!$F$2:$F$4000)} -> 0.21852326 | AH12: {=_xlfn.XLOOKUP(1,('1994 E Maize Soil VWC'!$C$2:$C$4000=$AA12)*('1994 E Maize Soil VWC'!$D$2:$D$4000=$AB12)*('1994 E Maize Soil VWC'!$E$2:$E$4000=AH$5),'1994 E Maize Soil VWC'!$F$2:$F$4000)} -> 0.22762467 | AI12: {=_xlfn.XLOOKUP(1,('1994 E Maize Soil VWC'!$C$2:$C$4000=$AA12)*('1994 E Maize Soil VWC'!$D$2:$D$4000=$AB12)*('1994 E Maize Soil VWC'!$E$2:$E$4000=AI$5),'1994 E Maize Soil VWC'!$F$2:$F$4000)} -> #N/A | AJ12: {=_xlfn.XLOOKUP(1,('1994 E Maize Soil VWC'!$C$2:$C$4000=$AA12)*('1994 E Maize Soil VWC'!$D$2:$D$4000=$AB12)*('1994 E Maize Soil VWC'!$E$2:$E$4000=AJ$5),'1994 E Maize Soil VWC'!$F$2:$F$4000)} -> 0.2614186 | ... AN12: {=_xlfn.XLOOKUP(1,('1994 E Maize Soil VWC'!$C$2:$C$4000=$AA12)*('1994 E Maize Soil VWC'!$D$2:$D$4000=$AB12)*('1994 E Maize Soil VWC'!$E$2:$E$4000=AN$5),'1994 E Maize Soil VWC'!$F$2:$F$4000)} -> 0.27336915 | AO12: =Z84 -> 210 | AP12: =AA84 -> 34544 | AQ12: =AVERAGE(AG84:AH90)*1400+AVERAGE(AG91:AH91)*100 -> 392.32737 | AR12: =AVERAGE(AC84:AF90)*1400+AVERAGE(AC91:AF91)*100 -> 417.72885 | AS12: =AVERAGE(AM84:AN90)*1400+AVERAGE(AM91:AN91)*100 -> 458.86965 | AT12: =AVERAGE(AJ84:AL90)*1400+AVERAGE(AJ91:AL91)*100 -> 454.81239 | AU12: =Z84 -> 210 | AV12: =AVERAGE(AC84:AD95)*2400 -> 605.0106 | AW12: =AVERAGE(AE84:AF95)*2400 -> 672.92867 | AX12: =AVERAGE(AG84:AH93)*2000 -> 520.64656 | AY12: =AVERAGE(AI84:AJ95)*2400 -> 698.89519 | AZ12: =AVERAGE(AK84:AL95)*2400 -> 687.86447 | BA12: =AVERAGE(AM84:AN93)*2000 -> 607.90049
AA13: =AA12 -> 34460 | AB13: =AB12+20 -> 150 | AC13: {=_xlfn.XLOOKUP(1,('1994 E Maize Soil VWC'!$C$2:$C$4000=$AA13)*('1994 E Maize Soil VWC'!$D$2:$D$4000=$AB13)*('1994 E Maize Soil VWC'!$E$2:$E$4000=AC$5),'1994 E Maize Soil VWC'!$F$2:$F$4000)} -> 0.26716964 | AD13: {=_xlfn.XLOOKUP(1,('1994 E Maize Soil VWC'!$C$2:$C$4000=$AA13)*('1994 E Maize Soil VWC'!$D$2:$D$4000=$AB13)*('1994 E Maize Soil VWC'!$E$2:$E$4000=AD$5),'1994 E Maize Soil VWC'!$F$2:$F$4000)} -> 0.17974334 | AE13: {=_xlfn.XLOOKUP(1,('1994 E Maize Soil VWC'!$C$2:$C$4000=$AA13)*('1994 E Maize Soil VWC'!$D$2:$D$4000=$AB13)*('1994 E Maize Soil VWC'!$E$2:$E$4000=AE$5),'1994 E Maize Soil VWC'!$F$2:$F$4000)} -> 0.28384237 | AF13: {=_xlfn.XLOOKUP(1,('1994 E Maize Soil VWC'!$C$2:$C$4000=$AA13)*('1994 E Maize Soil VWC'!$D$2:$D$4000=$AB13)*('1994 E Maize Soil VWC'!$E$2:$E$4000=AF$5),'1994 E Maize Soil VWC'!$F$2:$F$4000)} -> 0.27226115 | AG13: {=_xlfn.XLOOKUP(1,('1994 E Maize Soil VWC'!$C$2:$C$4000=$AA13)*('1994 E Maize Soil VWC'!$D$2:$D$4000=$AB13)*('1994 E Maize Soil VWC'!$E$2:$E$4000=AG$5),'1994 E Maize Soil VWC'!$F$2:$F$4000)} -> 0.25706576 | AH13: {=_xlfn.XLOOKUP(1,('1994 E Maize Soil VWC'!$C$2:$C$4000=$AA13)*('1994 E Maize Soil VWC'!$D$2:$D$4000=$AB13)*('1994 E Maize Soil VWC'!$E$2:$E$4000=AH$5),'1994 E Maize Soil VWC'!$F$2:$F$4000)} -> 0.26906907 | AI13: {=_xlfn.XLOOKUP(1,('1994 E Maize Soil VWC'!$C$2:$C$4000=$AA13)*('1994 E Maize Soil VWC'!$D$2:$D$4000=$AB13)*('1994 E Maize Soil VWC'!$E$2:$E$4000=AI$5),'1994 E Maize Soil VWC'!$F$2:$F$4000)} -> #N/A | AJ13: {=_xlfn.XLOOKUP(1,('1994 E Maize Soil VWC'!$C$2:$C$4000=$AA13)*('1994 E Maize Soil VWC'!$D$2:$D$4000=$AB13)*('1994 E Maize Soil VWC'!$E$2:$E$4000=AJ$5),'1994 E Maize Soil VWC'!$F$2:$F$4000)} -> 0.2807558 | ... AN13: {=_xlfn.XLOOKUP(1,('1994 E Maize Soil VWC'!$C$2:$C$4000=$AA13)*('1994 E Maize Soil VWC'!$D$2:$D$4000=$AB13)*('1994 E Maize Soil VWC'!$E$2:$E$4000=AN$5),'1994 E Maize Soil VWC'!$F$2:$F$4000)} -> 0.30790175 | AO13: =Z97 -> 223 | AP13: =AA97 -> 34557 | AQ13: =AVERAGE(AG97:AH103)*1400+AVERAGE(AG104:AH104)*100 -> 378.82656 | AR13: =AVERAGE(AC97:AF103)*1400+AVERAGE(AC104:AF104)*100 -> 408.34519 | AS13: =AVERAGE(AM97:AN103)*1400+AVERAGE(AM104:AN104)*100 -> 418.13082 | AT13: =AVERAGE(AJ97:AL103)*1400+AVERAGE(AJ104:AL104)*100 -> #N/A | AU13: =Z97 -> 223 | AV13: =AVERAGE(AC97:AD108)*2400 -> 597.96282 | AW13: =AVERAGE(AE97:AF108)*2400 -> 662.54267 | AX13: =AVERAGE(AG97:AH106)*2000 -> 507.44122 | AY13: =AVERAGE(AI97:AI108)*2400 -> 674.71756 | AZ13: =AVERAGE(AK97:AL108)*2400 -> 658.24466 | BA13: =AVERAGE(AM97:AN106)*2000 -> 570.07674
AA14: =AA13 -> 34460 | AB14: =AB13+20 -> 170 | AC14: {=_xlfn.XLOOKUP(1,('1994 E Maize Soil VWC'!$C$2:$C$4000=$AA14)*('1994 E Maize Soil VWC'!$D$2:$D$4000=$AB14)*('1994 E Maize Soil VWC'!$E$2:$E$4000=AC$5),'1994 E Maize Soil VWC'!$F$2:$F$4000)} -> 0.24522073 | AD14: {=_xlfn.XLOOKUP(1,('1994 E Maize Soil VWC'!$C$2:$C$4000=$AA14)*('1994 E Maize Soil VWC'!$D$2:$D$4000=$AB14)*('1994 E Maize Soil VWC'!$E$2:$E$4000=AD$5),'1994 E Maize Soil VWC'!$F$2:$F$4000)} -> 0.2601787 | AE14: {=_xlfn.XLOOKUP(1,('1994 E Maize Soil VWC'!$C$2:$C$4000=$AA14)*('1994 E Maize Soil VWC'!$D$2:$D$4000=$AB14)*('1994 E Maize Soil VWC'!$E$2:$E$4000=AE$5),'1994 E Maize Soil VWC'!$F$2:$F$4000)} -> 0.27732629 | AF14: {=_xlfn.XLOOKUP(1,('1994 E Maize Soil VWC'!$C$2:$C$4000=$AA14)*('1994 E Maize Soil VWC'!$D$2:$D$4000=$AB14)*('1994 E Maize Soil VWC'!$E$2:$E$4000=AF$5),'1994 E Maize Soil VWC'!$F$2:$F$4000)} -> 0.27220839 | AG14: {=_xlfn.XLOOKUP(1,('1994 E Maize Soil VWC'!$C$2:$C$4000=$AA14)*('1994 E Maize Soil VWC'!$D$2:$D$4000=$AB14)*('1994 E Maize Soil VWC'!$E$2:$E$4000=AG$5),'1994 E Maize Soil VWC'!$F$2:$F$4000)} -> 0.25057606 | AH14: {=_xlfn.XLOOKUP(1,('1994 E Maize Soil VWC'!$C$2:$C$4000=$AA14)*('1994 E Maize Soil VWC'!$D$2:$D$4000=$AB14)*('1994 E Maize Soil VWC'!$E$2:$E$4000=AH$5),'1994 E Maize Soil VWC'!$F$2:$F$4000)} -> 0.26484812 | AI14: {=_xlfn.XLOOKUP(1,('1994 E Maize Soil VWC'!$C$2:$C$4000=$AA14)*('1994 E Maize Soil VWC'!$D$2:$D$4000=$AB14)*('1994 E Maize Soil VWC'!$E$2:$E$4000=AI$5),'1994 E Maize Soil VWC'!$F$2:$F$4000)} -> #N/A | AJ14: {=_xlfn.XLOOKUP(1,('1994 E Maize Soil VWC'!$C$2:$C$4000=$AA14)*('1994 E Maize Soil VWC'!$D$2:$D$4000=$AB14)*('1994 E Maize Soil VWC'!$E$2:$E$4000=AJ$5),'1994 E Maize Soil VWC'!$F$2:$F$4000)} -> 0.2641886 | ... AN14: {=_xlfn.XLOOKUP(1,('1994 E Maize Soil VWC'!$C$2:$C$4000=$AA14)*('1994 E Maize Soil VWC'!$D$2:$D$4000=$AB14)*('1994 E Maize Soil VWC'!$E$2:$E$4000=AN$5),'1994 E Maize Soil VWC'!$F$2:$F$4000)} -> 0.27693057 | AO14: =Z110 -> 237 | AP14: =AA110 -> 34571 | AQ14: =AVERAGE(AG110:AH116)*1400+AVERAGE(AG117:AH117)*100 -> 370.79867 | AR14: =AVERAGE(AC110:AF116)*1400+AVERAGE(AC117:AF117)*100 -> 404.39236 | AS14: =AVERAGE(AM110:AN116)*1400+AVERAGE(AM117:AN117)*100 -> 394.44971 | AT14: =AVERAGE(AI110:AL116)*1400+AVERAGE(AI117:AL117)*100 -> 395.01811 | AU14: =Z110 -> 237 | AV14: =AVERAGE(AC110:AD121)*2400 -> 588.96202 | AW14: =AVERAGE(AE110:AF121)*2400 -> 664.43585 | AX14: =AVERAGE(AG110:AH119)*2000 -> 498.91605 | AY14: =AVERAGE(AI110:AJ121)*2400 -> 647.1313 | AZ14: =AVERAGE(AK110:AL121)*2400 -> 625.39841 | BA14: =AVERAGE(AM110:AN119)*2000 -> 545.11616
AA15: =AA14 -> 34460 | AB15: =AB14+20 -> 190 | AC15: {=_xlfn.XLOOKUP(1,('1994 E Maize Soil VWC'!$C$2:$C$4000=$AA15)*('1994 E Maize Soil VWC'!$D$2:$D$4000=$AB15)*('1994 E Maize Soil VWC'!$E$2:$E$4000=AC$5),'1994 E Maize Soil VWC'!$F$2:$F$4000)} -> 0.21512013 | AD15: {=_xlfn.XLOOKUP(1,('1994 E Maize Soil VWC'!$C$2:$C$4000=$AA15)*('1994 E Maize Soil VWC'!$D$2:$D$4000=$AB15)*('1994 E Maize Soil VWC'!$E$2:$E$4000=AD$5),'1994 E Maize Soil VWC'!$F$2:$F$4000)} -> 0.26347632 | AE15: {=_xlfn.XLOOKUP(1,('1994 E Maize Soil VWC'!$C$2:$C$4000=$AA15)*('1994 E Maize Soil VWC'!$D$2:$D$4000=$AB15)*('1994 E Maize Soil VWC'!$E$2:$E$4000=AE$5),'1994 E Maize Soil VWC'!$F$2:$F$4000)} -> 0.26479536 | AF15: {=_xlfn.XLOOKUP(1,('1994 E Maize Soil VWC'!$C$2:$C$4000=$AA15)*('1994 E Maize Soil VWC'!$D$2:$D$4000=$AB15)*('1994 E Maize Soil VWC'!$E$2:$E$4000=AF$5),'1994 E Maize Soil VWC'!$F$2:$F$4000)} -> 0.27009792 | AG15: {=_xlfn.XLOOKUP(1,('1994 E Maize Soil VWC'!$C$2:$C$4000=$AA15)*('1994 E Maize Soil VWC'!$D$2:$D$4000=$AB15)*('1994 E Maize Soil VWC'!$E$2:$E$4000=AG$5),'1994 E Maize Soil VWC'!$F$2:$F$4000)} -> 0.23261066 | AH15: {=_xlfn.XLOOKUP(1,('1994 E Maize Soil VWC'!$C$2:$C$4000=$AA15)*('1994 E Maize Soil VWC'!$D$2:$D$4000=$AB15)*('1994 E Maize Soil VWC'!$E$2:$E$4000=AH$5),'1994 E Maize Soil VWC'!$F$2:$F$4000)} -> 0.25598414 | AI15: {=_xlfn.XLOOKUP(1,('1994 E Maize Soil VWC'!$C$2:$C$4000=$AA15)*('1994 E Maize Soil VWC'!$D$2:$D$4000=$AB15)*('1994 E Maize Soil VWC'!$E$2:$E$4000=AI$5),'1994 E Maize Soil VWC'!$F$2:$F$4000)} -> #N/A | AJ15: {=_xlfn.XLOOKUP(1,('1994 E Maize Soil VWC'!$C$2:$C$4000=$AA15)*('1994 E Maize Soil VWC'!$D$2:$D$4000=$AB15)*('1994 E Maize Soil VWC'!$E$2:$E$4000=AJ$5),'1994 E Maize Soil VWC'!$F$2:$F$4000)} -> 0.25569395 | ... AN15: {=_xlfn.XLOOKUP(1,('1994 E Maize Soil VWC'!$C$2:$C$4000=$AA15)*('1994 E Maize Soil VWC'!$D$2:$D$4000=$AB15)*('1994 E Maize Soil VWC'!$E$2:$E$4000=AN$5),'1994 E Maize Soil VWC'!$F$2:$F$4000)} -> 0.28529332 | AO15: =Z123 -> 257 | AP15: =AA123 -> 34591 | AQ15: =AVERAGE(AG123:AH129)*1400+AVERAGE(AG130:AH130)*100 -> 384.83854 | AR15: =AVERAGE(AC123:AF129)*1400+AVERAGE(AC130:AF130)*100 -> 384.80804 | AS15: =AVERAGE(AM123:AN129)*1400+AVERAGE(AM130:AN130)*100 -> 413.27718 | AT15: =AVERAGE(AI123:AL129)*1400+AVERAGE(AI130:AL130)*100 -> 406.73807 | AU15: =Z123 -> 257 | AV15: =AVERAGE(AC123:AD134)*2400 -> 577.52862 | AW15: =AVERAGE(AE123:AF134)*2400 -> 635.62559 | AX15: =AVERAGE(AG123:AH132)*2000 -> 513.49145 | AY15: =AVERAGE(AI123:AJ134)*2400 -> 656.08092 | AZ15: =AVERAGE(AK123:AL134)*2400 -> 635.96191 | BA15: =AVERAGE(AM123:AN132)*2000 -> 563.52022
AA16: =AA15 -> 34460 | AB16: =AB15+20 -> 210 | AC16: {=_xlfn.XLOOKUP(1,('1994 E Maize Soil VWC'!$C$2:$C$4000=$AA16)*('1994 E Maize Soil VWC'!$D$2:$D$4000=$AB16)*('1994 E Maize Soil VWC'!$E$2:$E$4000=AC$5),'1994 E Maize Soil VWC'!$F$2:$F$4000)} -> 0.18610114 | AD16: {=_xlfn.XLOOKUP(1,('1994 E Maize Soil VWC'!$C$2:$C$4000=$AA16)*('1994 E Maize Soil VWC'!$D$2:$D$4000=$AB16)*('1994 E Maize Soil VWC'!$E$2:$E$4000=AD$5),'1994 E Maize Soil VWC'!$F$2:$F$4000)} -> 0.25255462 | AE16: {=_xlfn.XLOOKUP(1,('1994 E Maize Soil VWC'!$C$2:$C$4000=$AA16)*('1994 E Maize Soil VWC'!$D$2:$D$4000=$AB16)*('1994 E Maize Soil VWC'!$E$2:$E$4000=AE$5),'1994 E Maize Soil VWC'!$F$2:$F$4000)} -> 0.24366426 | AF16: {=_xlfn.XLOOKUP(1,('1994 E Maize Soil VWC'!$C$2:$C$4000=$AA16)*('1994 E Maize Soil VWC'!$D$2:$D$4000=$AB16)*('1994 E Maize Soil VWC'!$E$2:$E$4000=AF$5),'1994 E Maize Soil VWC'!$F$2:$F$4000)} -> 0.26661564 | AG16: {=_xlfn.XLOOKUP(1,('1994 E Maize Soil VWC'!$C$2:$C$4000=$AA16)*('1994 E Maize Soil VWC'!$D$2:$D$4000=$AB16)*('1994 E Maize Soil VWC'!$E$2:$E$4000=AG$5),'1994 E Maize Soil VWC'!$F$2:$F$4000)} -> #N/A | AH16: {=_xlfn.XLOOKUP(1,('1994 E Maize Soil VWC'!$C$2:$C$4000=$AA16)*('1994 E Maize Soil VWC'!$D$2:$D$4000=$AB16)*('1994 E Maize Soil VWC'!$E$2:$E$4000=AH$5),'1994 E Maize Soil VWC'!$F$2:$F$4000)} -> #N/A | AI16: {=_xlfn.XLOOKUP(1,('1994 E Maize Soil VWC'!$C$2:$C$4000=$AA16)*('1994 E Maize Soil VWC'!$D$2:$D$4000=$AB16)*('1994 E Maize Soil VWC'!$E$2:$E$4000=AI$5),'1994 E Maize Soil VWC'!$F$2:$F$4000)} -> #N/A | AJ16: {=_xlfn.XLOOKUP(1,('1994 E Maize Soil VWC'!$C$2:$C$4000=$AA16)*('1994 E Maize Soil VWC'!$D$2:$D$4000=$AB16)*('1994 E Maize Soil VWC'!$E$2:$E$4000=AJ$5),'1994 E Maize Soil VWC'!$F$2:$F$4000)} -> 0.24400721 | ... AN16: {=_xlfn.XLOOKUP(1,('1994 E Maize Soil VWC'!$C$2:$C$4000=$AA16)*('1994 E Maize Soil VWC'!$D$2:$D$4000=$AB16)*('1994 E Maize Soil VWC'!$E$2:$E$4000=AN$5),'1994 E Maize Soil VWC'!$F$2:$F$4000)} -> #N/A | AO16: =Z136 -> 0 | AP16: =AA136 -> 34334 | AQ16: =AVERAGE(AG136:AH142)*1400+AVERAGE(AG143:AH143)*100 -> #N/A | AR16: =AVERAGE(AC136:AF142)*1400+AVERAGE(AC143:AF143)*100 -> #N/A | AS16: =AVERAGE(AM136:AN142)*1400+AVERAGE(AM143:AN143)*100 -> #N/A | AT16: =AVERAGE(AI136:AL142)*1400+AVERAGE(AI143:AL143)*100 -> #N/A | AU16: =Z136 -> 0 | AV16: =AVERAGE(AC136:AD147)*2400 -> #N/A | AW16: =AVERAGE(AE136:AF147)*2400 -> #N/A | AX16: =AVERAGE(AG136:AH145)*2000 -> #N/A | AY16: =AVERAGE(AI136:AJ147)*2400 -> #N/A | AZ16: =AVERAGE(AK136:AL147)*2400 -> #N/A | BA16: =AVERAGE(AM136:AN145)*2000 -> #N/A
AA17: =AA16 -> 34460 | AB17: =AB16+20 -> 230 | AC17: {=_xlfn.XLOOKUP(1,('1994 E Maize Soil VWC'!$C$2:$C$4000=$AA17)*('1994 E Maize Soil VWC'!$D$2:$D$4000=$AB17)*('1994 E Maize Soil VWC'!$E$2:$E$4000=AC$5),'1994 E Maize Soil VWC'!$F$2:$F$4000)} -> 0.17615554 | AD17: {=_xlfn.XLOOKUP(1,('1994 E Maize Soil VWC'!$C$2:$C$4000=$AA17)*('1994 E Maize Soil VWC'!$D$2:$D$4000=$AB17)*('1994 E Maize Soil VWC'!$E$2:$E$4000=AD$5),'1994 E Maize Soil VWC'!$F$2:$F$4000)} -> 0.23551256 | AE17: {=_xlfn.XLOOKUP(1,('1994 E Maize Soil VWC'!$C$2:$C$4000=$AA17)*('1994 E Maize Soil VWC'!$D$2:$D$4000=$AB17)*('1994 E Maize Soil VWC'!$E$2:$E$4000=AE$5),'1994 E Maize Soil VWC'!$F$2:$F$4000)} -> 0.23965436 | AF17: {=_xlfn.XLOOKUP(1,('1994 E Maize Soil VWC'!$C$2:$C$4000=$AA17)*('1994 E Maize Soil VWC'!$D$2:$D$4000=$AB17)*('1994 E Maize Soil VWC'!$E$2:$E$4000=AF$5),'1994 E Maize Soil VWC'!$F$2:$F$4000)} -> 0.25622157 | AG17: {=_xlfn.XLOOKUP(1,('1994 E Maize Soil VWC'!$C$2:$C$4000=$AA17)*('1994 E Maize Soil VWC'!$D$2:$D$4000=$AB17)*('1994 E Maize Soil VWC'!$E$2:$E$4000=AG$5),'1994 E Maize Soil VWC'!$F$2:$F$4000)} -> #N/A | AH17: {=_xlfn.XLOOKUP(1,('1994 E Maize Soil VWC'!$C$2:$C$4000=$AA17)*('1994 E Maize Soil VWC'!$D$2:$D$4000=$AB17)*('1994 E Maize Soil VWC'!$E$2:$E$4000=AH$5),'1994 E Maize Soil VWC'!$F$2:$F$4000)} -> #N/A | AI17: {=_xlfn.XLOOKUP(1,('1994 E Maize Soil VWC'!$C$2:$C$4000=$AA17)*('1994 E Maize Soil VWC'!$D$2:$D$4000=$AB17)*('1994 E Maize Soil VWC'!$E$2:$E$4000=AI$5),'1994 E Maize Soil VWC'!$F$2:$F$4000)} -> #N/A | AJ17: {=_xlfn.XLOOKUP(1,('1994 E Maize Soil VWC'!$C$2:$C$4000=$AA17)*('1994 E Maize Soil VWC'!$D$2:$D$4000=$AB17)*('1994 E Maize Soil VWC'!$E$2:$E$4000=AJ$5),'1994 E Maize Soil VWC'!$F$2:$F$4000)} -> 0.25210615 | ... AN17: {=_xlfn.XLOOKUP(1,('1994 E Maize Soil VWC'!$C$2:$C$4000=$AA17)*('1994 E Maize Soil VWC'!$D$2:$D$4000=$AB17)*('1994 E Maize Soil VWC'!$E$2:$E$4000=AN$5),'1994 E Maize Soil VWC'!$F$2:$F$4000)} -> #N/A | AO17: =Z149 -> 0 | AP17: =AA149 -> 34334 | AQ17: =AVERAGE(AG149:AH155)*1400+AVERAGE(AG156:AH156)*100 -> #N/A | AR17: =AVERAGE(AC149:AF155)*1400+AVERAGE(AC156:AF156)*100 -> #N/A | AS17: =AVERAGE(AM149:AN155)*1400+AVERAGE(AM156:AN156)*100 -> #N/A | AT17: =AVERAGE(AI149:AL155)*1400+AVERAGE(AI156:AL156)*100 -> #N/A | AU17: =Z149 -> 0 | AV17: =AVERAGE(AC149:AD160)*2400 -> #N/A | AW17: =AVERAGE(AE149:AF160)*2400 -> #N/A | AX17: =AVERAGE(AG149:AH158)*2000 -> #N/A | AY17: =AVERAGE(AI149:AJ160)*2400 -> #N/A | AZ17: =AVERAGE(AK149:AL160)*2400 -> #N/A | BA17: =AVERAGE(AM149:AN158)*2000 -> #N/A
AO18: =Z162 -> 0 | AP18: =AA162 -> 34334 | AQ18: =AVERAGE(AG162:AH168)*1400+AVERAGE(AG169:AH169)*100 -> #N/A | AR18: =AVERAGE(AC162:AF168)*1400+AVERAGE(AC169:AF169)*100 -> #N/A | AS18: =AVERAGE(AM162:AN168)*1400+AVERAGE(AM169:AN169)*100 -> #N/A | AT18: =AVERAGE(AI162:AL168)*1400+AVERAGE(AI169:AL169)*100 -> #N/A | AU18: =Z162 -> 0 | AV18: =AVERAGE(AC162:AD173)*2400 -> #N/A | AW18: =AVERAGE(AE162:AF173)*2400 -> #N/A | AX18: =AVERAGE(AG162:AH171)*2000 -> #N/A | AY18: =AVERAGE(AI162:AJ173)*2400 -> #N/A | AZ18: =AVERAGE(AK162:AL173)*2400 -> #N/A | BA18: =AVERAGE(AM162:AN171)*2000 -> #N/A
Y19: =Y6 -> 1994 | Z19: 140 | AA19: =DATE(Y19,1,Z19) -> 34474 | AB19: 10 | AC19: {=_xlfn.XLOOKUP(1,('1994 E Maize Soil VWC'!$C$2:$C$4000=$AA19)*('1994 E Maize Soil VWC'!$D$2:$D$4000=$AB19)*('1994 E Maize Soil VWC'!$E$2:$E$4000=AC$5),'1994 E Maize Soil VWC'!$F$2:$F$4000)} -> 0.25092086 | AD19: {=_xlfn.XLOOKUP(1,('1994 E Maize Soil VWC'!$C$2:$C$4000=$AA19)*('1994 E Maize Soil VWC'!$D$2:$D$4000=$AB19)*('1994 E Maize Soil VWC'!$E$2:$E$4000=AD$5),'1994 E Maize Soil VWC'!$F$2:$F$4000)} -> 0.23015283 | AE19: {=_xlfn.XLOOKUP(1,('1994 E Maize Soil VWC'!$C$2:$C$4000=$AA19)*('1994 E Maize Soil VWC'!$D$2:$D$4000=$AB19)*('1994 E Maize Soil VWC'!$E$2:$E$4000=AE$5),'1994 E Maize Soil VWC'!$F$2:$F$4000)} -> 0.2532879 | AF19: {=_xlfn.XLOOKUP(1,('1994 E Maize Soil VWC'!$C$2:$C$4000=$AA19)*('1994 E Maize Soil VWC'!$D$2:$D$4000=$AB19)*('1994 E Maize Soil VWC'!$E$2:$E$4000=AF$5),'1994 E Maize Soil VWC'!$F$2:$F$4000)} -> 0.2384375 | AG19: {=_xlfn.XLOOKUP(1,('1994 E Maize Soil VWC'!$C$2:$C$4000=$AA19)*('1994 E Maize Soil VWC'!$D$2:$D$4000=$AB19)*('1994 E Maize Soil VWC'!$E$2:$E$4000=AG$5),'1994 E Maize Soil VWC'!$F$2:$F$4000)} -> 0.21893753 | AH19: {=_xlfn.XLOOKUP(1,('1994 E Maize Soil VWC'!$C$2:$C$4000=$AA19)*('1994 E Maize Soil VWC'!$D$2:$D$4000=$AB19)*('1994 E Maize Soil VWC'!$E$2:$E$4000=AH$5),'1994 E Maize Soil VWC'!$F$2:$F$4000)} -> 0.20913119 | AI19: {=_xlfn.XLOOKUP(1,('1994 E Maize Soil VWC'!$C$2:$C$4000=$AA19)*('1994 E Maize Soil VWC'!$D$2:$D$4000=$AB19)*('1994 E Maize Soil VWC'!$E$2:$E$4000=AI$5),'1994 E Maize Soil VWC'!$F$2:$F$4000)} -> #N/A | AJ19: {=_xlfn.XLOOKUP(1,('1994 E Maize Soil VWC'!$C$2:$C$4000=$AA19)*('1994 E Maize Soil VWC'!$D$2:$D$4000=$AB19)*('1994 E Maize Soil VWC'!$E$2:$E$4000=AJ$5),'1994 E Maize Soil VWC'!$F$2:$F$4000)} -> 0.25523227 | ... AN19: {=_xlfn.XLOOKUP(1,('1994 E Maize Soil VWC'!$C$2:$C$4000=$AA19)*('1994 E Maize Soil VWC'!$D$2:$D$4000=$AB19)*('1994 E Maize Soil VWC'!$E$2:$E$4000=AN$5),'1994 E Maize Soil VWC'!$F$2:$F$4000)} -> 0.23347797 | AO19: =Z175 -> 0 | AP19: =AA175 -> 34334 | AQ19: =AVERAGE(AG175:AH181)*1400+AVERAGE(AG182:AH182)*100 -> #N/A | AR19: =AVERAGE(AC175:AF181)*1400+AVERAGE(AC182:AF182)*100 -> #N/A | AS19: =AVERAGE(AM175:AN181)*1400+AVERAGE(AM182:AN182)*100 -> #N/A | AT19: =AVERAGE(AI175:AL181)*1400+AVERAGE(AI182:AL182)*100 -> #N/A | AU19: =Z175 -> 0 | AV19: =AVERAGE(AC175:AD186)*2400 -> #N/A | AW19: =AVERAGE(AE175:AF186)*2400 -> #N/A | AX19: =AVERAGE(AG175:AH184)*2000 -> #N/A | AY19: =AVERAGE(AI175:AJ186)*2400 -> #N/A | AZ19: =AVERAGE(AK175:AL186)*2400 -> #N/A | BA19: =AVERAGE(AM175:AN184)*2000 -> #N/A
AA20: =AA19 -> 34474 | AB20: =AB19+20 -> 30 | AC20: {=_xlfn.XLOOKUP(1,('1994 E Maize Soil VWC'!$C$2:$C$4000=$AA20)*('1994 E Maize Soil VWC'!$D$2:$D$4000=$AB20)*('1994 E Maize Soil VWC'!$E$2:$E$4000=AC$5),'1994 E Maize Soil VWC'!$F$2:$F$4000)} -> 0.21292918 | AD20: {=_xlfn.XLOOKUP(1,('1994 E Maize Soil VWC'!$C$2:$C$4000=$AA20)*('1994 E Maize Soil VWC'!$D$2:$D$4000=$AB20)*('1994 E Maize Soil VWC'!$E$2:$E$4000=AD$5),'1994 E Maize Soil VWC'!$F$2:$F$4000)} -> 0.18383769 | AE20: {=_xlfn.XLOOKUP(1,('1994 E Maize Soil VWC'!$C$2:$C$4000=$AA20)*('1994 E Maize Soil VWC'!$D$2:$D$4000=$AB20)*('1994 E Maize Soil VWC'!$E$2:$E$4000=AE$5),'1994 E Maize Soil VWC'!$F$2:$F$4000)} -> 0.26379901 | AF20: {=_xlfn.XLOOKUP(1,('1994 E Maize Soil VWC'!$C$2:$C$4000=$AA20)*('1994 E Maize Soil VWC'!$D$2:$D$4000=$AB20)*('1994 E Maize Soil VWC'!$E$2:$E$4000=AF$5),'1994 E Maize Soil VWC'!$F$2:$F$4000)} -> 0.25851551 | AG20: {=_xlfn.XLOOKUP(1,('1994 E Maize Soil VWC'!$C$2:$C$4000=$AA20)*('1994 E Maize Soil VWC'!$D$2:$D$4000=$AB20)*('1994 E Maize Soil VWC'!$E$2:$E$4000=AG$5),'1994 E Maize Soil VWC'!$F$2:$F$4000)} -> 0.30352194 | AH20: {=_xlfn.XLOOKUP(1,('1994 E Maize Soil VWC'!$C$2:$C$4000=$AA20)*('1994 E Maize Soil VWC'!$D$2:$D$4000=$AB20)*('1994 E Maize Soil VWC'!$E$2:$E$4000=AH$5),'1994 E Maize Soil VWC'!$F$2:$F$4000)} -> 0.2217565 | AI20: {=_xlfn.XLOOKUP(1,('1994 E Maize Soil VWC'!$C$2:$C$4000=$AA20)*('1994 E Maize Soil VWC'!$D$2:$D$4000=$AB20)*('1994 E Maize Soil VWC'!$E$2:$E$4000=AI$5),'1994 E Maize Soil VWC'!$F$2:$F$4000)} -> #N/A | AJ20: {=_xlfn.XLOOKUP(1,('1994 E Maize Soil VWC'!$C$2:$C$4000=$AA20)*('1994 E Maize Soil VWC'!$D$2:$D$4000=$AB20)*('1994 E Maize Soil VWC'!$E$2:$E$4000=AJ$5),'1994 E Maize Soil VWC'!$F$2:$F$4000)} -> 0.25854773 | ... AN20: {=_xlfn.XLOOKUP(1,('1994 E Maize Soil VWC'!$C$2:$C$4000=$AA20)*('1994 E Maize Soil VWC'!$D$2:$D$4000=$AB20)*('1994 E Maize Soil VWC'!$E$2:$E$4000=AN$5),'1994 E Maize Soil VWC'!$F$2:$F$4000)} -> 0.29682091 | AO20: =Z188 -> 0 | AP20: =AA188 -> 34334 | AQ20: =AVERAGE(AG188:AH194)*1400+AVERAGE(AG195:AH195)*100 -> #N/A | AR20: =AVERAGE(AC188:AF194)*1400+AVERAGE(AC195:AF195)*100 -> #N/A | AS20: =AVERAGE(AM188:AN194)*1400+AVERAGE(AM195:AN195)*100 -> #N/A | AT20: =AVERAGE(AI188:AL194)*1400+AVERAGE(AI195:AL195)*100 -> #N/A | AU20: =Z188 -> 0 | AV20: =AVERAGE(AC188:AD199)*2400 -> #N/A | AW20: =AVERAGE(AE188:AF199)*2400 -> #N/A | AX20: =AVERAGE(AG188:AH197)*2000 -> #N/A | AY20: =AVERAGE(AI188:AJ199)*2400 -> #N/A | AZ20: =AVERAGE(AK188:AL199)*2400 -> #N/A | BA20: =AVERAGE(AM188:AN199)*2400 -> #N/A
