Workbook

Sheet 2013 E Maize VWC Introduction
A1: SHEET NAME | B1: CONTENTS
A2: 2013 E Maize VWC Introduction | B2: Explanation of sheet names and contents, authors of the data, key references to methods, symbols, conventions, where VWC stands for volumetric water content.
A3: Dic. 2013 E Maize Profile WC | B3: Data dictionary for sheet or CSV file named "2013 E Maize Profile WC" where WC stands for depth of water in a soil profile of defined depth.
A4: 2013 E Maize Profile WC | B4: Summary data of soil profile water content in mm for each tube and date of neutron probe reading for the entire season.
A5: Dic. 2013 E Maize Soil VWC | B5: Data dictionary for sheet or CSV file named "2013 E Maize Soil VWC"
A6: 2013 E Maize Soil VWC | B6: Soil water content (vol/vol) for each date of reading and each depth of reading in each access tube.
A7: Dic. 2013 E Maize Tube Map | B7: Data dictionary for sheet or CSV file named "2013 E Maize Tube Map"
A8: 2013 E Maize Tube Map | B8: Mapping of tube locations within each field and lysimeter by latitude and longitude
A9: 2013 E Maize VWC Graphs | B9: Graphs of the water content profile for all dates when data were taken with one graph for each neutron probe access tube. Also contain summary data of profile water content at each tube location for each date when data were taken.
A10: Data in this spreadsheet are the result of a team effort at the USDA-ARS Conservation & Production Research Laboratory, Soil and Water Management Research Unit (SWMRU).
A11: The scientists responsible for collecting these data, calibrating the instruments, quality control and data analysis are:
A12: Author | B12: Steven R. Evett, Research Soil Scientist (point of contact and responsible for this spreadsheet), Steve.Evett@usda.gov, 806-356-5775, srevett1948@gmail.com
A13: Author | B13: Paul D. Colaizzi, Research Agricultural Engineer, paul.colaizzi@usda.gov
A14: Author | B14: Karen S. Copeland, Soil Scientist, Karen.Copeland@usda.gov, 806-356-5735
A15: Author | B15: Brice B. Ruthardt, Biological Scientist, Brice.Ruthardt@usda.gov, 806-356-5780
A16: All are or were employed in the
A17: USDA-ARS Conservation & Production Research Laboratory
A18: 300 Simmons Road, Unit 10
A19: Bushland, Texas 79012 USA
A20: Persons using these data for scientific research and publication are responsible for:
A21: 1. Contacting all the scientists listed above and obtaining approval to use the data,
A22: 2. Inviting them to be involved in said research, and
A23: 3. Inviting them to be involved as coauthors in the data analysis, drafting and critical review of any publications resulting from the research.
A24: Data contained herein are from experiments in the large weighing lysimeter fields at Bushland, Texas. Neutron count measurements were taken using a model 503DR1.5 HydroProbe manufactured by Campbell Pacific Nuclear, a division of Instrotek, Inc., Concord, California. Soil horizon-specific calibrations were established at field sites using methods described by Evett (2003) and Evett et al. (2008).
A25: REFERENCES:
A26: Evett, S.R. and J.L. Steiner. 1995. Precision of neutron scattering and capacitance type soil water content gauges from field calibration. Soil Sci. Soc. Am. J. 59(4):961-968. https://doi.org/10.2136/sssaj1995.03615995005900040001x
A27: Evett, S.R. 2003a. Soil Water Measurement by Neutron Thermalization. In B.A. Stewart and Terry A. Howell (editors). Encyclopedia of Water Science, Marcel Dekker, Inc. New York. Pp. 889-893.
... A29: Evett, S.R., L.K. Heng, P. Moutonnet and M.L. Nguyen. 2008. Field Estimation of Soil Water Content: A Practical Guide to Methods, Instrumentation, and Sensor Technology. 131 pp. IAEA-TCS-30. International Atomic Energy Agency, Vienna, Austria. ISSN 1018–5518. Available at http://www-pub.iaea.org/mtcd/publications/PubDetails.asp?pubId=7801
A30: CONVENTION | B30: EXPLANATION
A31: Water content | B31: Water content data are in units of volume per unit volume of soil (m3/m3). The neutron probe was used to take readings of neutron counts at each depth in each access tube and to take standard count and Chi ratio statistics with the neutron probe locked within its shield, which was mounted on top of a depth control stand (Evett et al., 2003b). Count ratio data (count divided by long-term mean of standard counts) were converted to water content data using calibrations done in the field as described Evett and Steiner (1995) and Evett et al. (2003a, 2008). Methods for calibration and use of the neutron probe are given in the references (Evett et al., 2003a, 2008). The data have several significant digits after the decimal point but there are only approximately three significant digits after the decimal point. Accuracy of the 10-cm data were improved by use of a depth control stand and a separate calibration for that depth.
A32: Depth | B32: Depths shown are the center depths of sensing with the neutron probe
A33: Porosity | B33: Soil porosity by depth as determined from prior research that determined soil bulk density and porosity values by depth. The porosity is the air-filled pore space as a volume fraction of a unit soil volume when the soil is completely dry. Calculated from dry bulk density (BD, Mg/m3) as: Porosity = 1 - BD/2.65, where 2.65 is the particle density (Mg/m3) of quartz sand. The porosity represents a quality control limit to soil water content data. Soil water content should not be larger than porosity. Notwithstanding its use as a limit, in the case of swelling soils the water content at saturation can be somewhat larger than the porosity that is calculated from dry bulk density.
A34: SYMBOL | B34: MEANING
A35: DAP | B35: Days after planting
A36: DOY | B36: day of year. January 1 is DOY 1, February 1 is DOY 32, etc.
A37: FC | B37: Soil profile water content in mm
A38: VWC | B38: Volumetric water content in units of volume of water per unit volume of soil.
A39: WC | B39: Soil profile water content. Also known as soil profile water storage. Units are typically in depth of water, e.g., mm, in a soil profile from the soil surface to a defined depth.
A40: MAD | B40: Profile water content in mm at management allowed depletion
A41: NE | B41: northeast. Refers to NE field and weighing lysimeter
...

Sheet DIc. 2013 E Maize Profile WC
A1: Spreadsheet tab | B1: Element or value display name | C1: Description | D1: Data type | E1: Character length | F1: Acceptable values | G1: Required? | H1: Accepts null value?
A2: 2013 E Maize Profile WC | B2: DAP | C2: Year | D2: integer | E2: 3 | G2: Yes | H2: No
A3: 2013 E Maize Profile WC | B3: DOY | C3: Serial day of the year beginning with 1 for January 1. | D3: integer | E3: 3 | F3: 1 to 366 | G3: Yes | H3: No
A4: 2013 E Maize Profile WC | B4: Storage in top 1.5 m of soil in NE Lys | C4: Water in mm stored in top 1.5 m of soil in NE Lys | D4: decimal | G4: Yes | H4: Yes, #N/A
A5: 2013 E Maize Profile WC | B5: Storage in top 1.5 m of soil in NE Field | C5: Water in mm stored in top 1.5 m of soil in NE Field | D5: decimal | G5: Yes | H5: Yes, #N/A
A6: 2013 E Maize Profile WC | B6: Storage in top 1.5 m of soil in SE Lys | C6: Water in mm stored in top 1.5 m of soil in SE Lys | D6: decimal | G6: Yes | H6: Yes, #N/A
A7: 2013 E Maize Profile WC | B7: Storage in top 1.5 m of soil in SE Field | C7: Water in mm stored in top 1.5 m of soil in SE Field | D7: decimal | G7: Yes | H7: Yes, #N/A
A8: 2013 E Maize Profile WC | B8: FC | C8: Water in mm stored in top 1.5 m of soil at field capacity | D8: decimal | G8: Yes | H8: Yes, #N/A
A9: 2013 E Maize Profile WC | B9: PWP | C9: Water in mm stored in top 1.5 m of soil at permanent wilting point | D9: decimal | G9: Yes | H9: Yes, #N/A
A10: 2013 E Maize Profile WC | B10: MAD | C10: Water in mm stored in top 1.5 m of soil at management allowed depletion | D10: decimal | G10: Yes | H10: Yes, #N/A
A11: 2013 E Maize Profile WC | B11: Storage in top 2.4 m of NE field tubes 1-2 | C11: Water in mm stored in top 2.4 m of NE field tubes 1-2 | D11: decimal | G11: Yes | H11: Yes, #N/A
A12: 2013 E Maize Profile WC | B12: Storage in top 2.4 m of NE field tubes 3-4 | C12: Water in mm stored in top 2.4 m of NE field tubes 3-4 | D12: decimal | G12: Yes | H12: Yes, #N/A
A13: 2013 E Maize Profile WC | B13: Storage in top 2.0 m of NE Lys tubes 5-6 | C13: Water in mm stored in top 2.0 m of NE Lys tubes 5-6 | D13: decimal | G13: Yes | H13: Yes, #N/A
A14: 2013 E Maize Profile WC | B14: Storage in top 2.4 m of NE field tubes 7-8 | C14: Water in mm stored in top 2.4 m of NE field tubes 7-8 | D14: decimal | G14: Yes | H14: Yes, #N/A
A15: 2013 E Maize Profile WC | B15: Storage in top 2.4 m of NE field tubes 9-10 | C15: Water in mm stored in top 2.4 m of NE field tubes 9-10 | D15: decimal | G15: Yes | H15: Yes, #N/A
... A20: 2013 E Maize Profile WC | B20: Storage in top 2.4 m of SE field tubes 19-20 | C20: Water in mm stored in top 2.4 m of SE field tubes 19-20 | D20: decimal | G20: Yes | H20: Yes, #N/A

Sheet 2013 E Maize Profile WC
A1: DAP | B1: DOY | C1: Water (mm) stored in top 1.5 m of soil in NE Lys | D1: Water (mm) stored in top 1.5 m of soil in NE Field | E1: Water (mm) stored in top 1.5 m of soil in SE Lys | F1: Water (mm) stored in top 1.5 m of soil in SE Field | G1: FC | H1: PWP | I1: MAD | J1: Water stored (mm) in top 2.4 m of NE field tubes 1-2 | K1: Water stored (mm) in top 2.4 m of NE field tubes 3-4 | L1: Water stored (mm) in top 2.0 m of NE Lys tubes 5-6 | M1: Water stored (mm) in top 2.4 m of NE field tubes 7-8 | N1: Water stored (mm) in top 2.4 m of NE field tubes 9-10 | O1: Water stored (mm) in top 2.4 m of SE field tubes 11-12 | P1: Water stored (mm) in top 2.4 m of SE field tubes 13-14 | Q1: Water stored (mm) in top 2.0 m of SE Lys tubes 15-16 | R1: Water stored (mm) in top 2.4 m of SE field tubes 17-18 | S1: Water stored (mm) in top 2.4 m of SE field tubes 19-20
A2: 15 | B2: 157 | C2: 519.51406 | D2: #N/A | E2: 508.71275 | F2: #N/A | G2: 495 | H2: 270 | I2: 360 | J2: #N/A | K2: #N/A | L2: 687.2538 | M2: #N/A | N2: #N/A | O2: #N/A | P2: #N/A | Q2: 671.208 | R2: #N/A | S2: #N/A
A3: 29 | B3: 171 | C3: 491.36777 | D3: 498.84464 | E3: 477.96338 | F3: 488.92375 | G3: 495 | H3: 270 | I3: 360 | J3: 766.93757 | K3: 751.35444 | L3: 657.68508 | M3: 773.32593 | N3: 775.20466 | O3: 773.60151 | P3: 760.18509 | Q3: 641.47747 | R3: 779.3813 | S3: 759.84059
A4: 34 | B4: 176 | C4: 475.36297 | D4: 488.56182 | E4: 460.79909 | F4: 481.37142 | G4: 495 | H4: 270 | I4: 360 | J4: 761.10965 | K4: 743.99529 | L4: 643.6486 | M4: 761.08425 | N4: 760.05023 | O4: 767.8633 | P4: 752.43746 | Q4: 624.65771 | R4: 770.94408 | S4: 752.89625
A5: 41 | B5: 183 | C5: 456.07393 | D5: 480.07498 | E5: 444.1267 | F5: 464.43469 | G5: 495 | H5: 270 | I5: 360 | J5: 743.27934 | K5: 729.86029 | L5: 623.86235 | M5: 761.91323 | N5: 752.30909 | O5: 749.47797 | P5: 737.33697 | Q5: 608.67144 | R5: 755.71128 | S5: 738.92724
A6: 47 | B6: 189 | C6: 459.89126 | D6: 493.56863 | E6: 443.71051 | F6: 479.82985 | G6: 495 | H6: 270 | I6: 360 | J6: 760.8071 | K6: 747.56899 | L6: 628.91978 | M6: 776.75582 | N6: 763.09037 | O6: 763.88475 | P6: 754.06791 | Q6: 608.92767 | R6: 770.27881 | S6: 752.56223
A7: 55 | B7: 197 | C7: 445.79682 | D7: 485.09249 | E7: 433.5371 | F7: #N/A | G7: 495 | H7: 270 | I7: 360 | J7: 761.23588 | K7: 730.68937 | L7: 612.812 | M7: 767.78707 | N7: 747.83517 | O7: 769.97203 | P7: 753.24608 | Q7: 597.48283 | R7: #N/A | S7: #N/A
A8: 61 | B8: 203 | C8: 487.84113 | D8: 502.7873 | E8: 469.98712 | F8: 488.64634 | G8: 495 | H8: 270 | I8: 360 | J8: 768.47153 | K8: 759.84676 | L8: 657.18776 | M8: 779.4726 | N8: 771.34825 | O8: 770.10321 | P8: 763.96475 | Q8: 635.51847 | R8: 780.79103 | S8: 760.16217
A9: 68 | B9: 210 | C9: 441.97995 | D9: 462.97863 | E9: 418.34027 | F9: 446.608 | G9: 495 | H9: 270 | I9: 360 | J9: 724.72467 | K9: 717.3211 | L9: 610.19119 | M9: 739.96747 | N9: 730.17646 | O9: 723.79717 | P9: 716.01786 | Q9: 582.50036 | R9: 739.95839 | S9: 722.48533
A10: 76 | B10: 218 | C10: 437.10029 | D10: 457.46316 | E10: 419.73272 | F10: 446.92444 | G10: 495 | H10: 270 | I10: 360 | J10: 723.8507 | K10: 706.33722 | L10: 603.24044 | M10: 731.67619 | N10: 718.20677 | O10: 726.17446 | P10: 714.29174 | Q10: 582.37668 | R10: 737.0737 | S10: 720.58663
A11: 89 | B11: 231 | C11: 480.21012 | D11: 482.14194 | E11: 458.69814 | F11: 473.03769 | G11: 495 | H11: 270 | I11: 360 | J11: 747.06675 | K11: 730.57817 | L11: 647.06185 | M11: 750.85049 | N11: 744.22999 | O11: 751.83112 | P11: 741.12738 | Q11: 621.87259 | R11: 764.77272 | S11: 741.40886
A12: 104 | B12: 246 | C12: 439.53013 | D12: 432.73597 | E12: 404.66966 | F12: 419.18665 | G12: 495 | H12: 270 | I12: 360 | J12: 689.47147 | K12: 676.356 | L12: 605.42852 | M12: 704.58556 | N12: 690.98953 | O12: 693.00076 | P12: 679.5873 | Q12: 569.12337 | R12: 707.95284 | S12: 686.26023
A13: 111 | B13: 253 | C13: 427.98358 | D13: 420.81245 | E13: 403.41662 | F13: 414.43387 | G13: 495 | H13: 270 | I13: 360 | J13: 678.30766 | K13: 662.00201 | L13: 592.20141 | M13: 691.30899 | N13: 674.95354 | O13: 699.28922 | P13: 668.95298 | Q13: 566.03219 | R13: 697.50404 | S13: 677.14302
A14: 127 | B14: 269 | C14: 436.86972 | D14: 428.8739 | E14: 416.18995 | F14: 418.99131 | G14: 495 | H14: 270 | I14: 360 | J14: 681.0152 | K14: 664.9376 | L14: 600.65787 | M14: 698.2462 | N14: 682.97544 | O14: 698.71402 | P14: 678.97547 | Q14: 579.1569 | R14: 698.40234 | S14: 676.135

Sheet Dic. 2013 E Maize Soil VWC
A1: Spreadsheet tab | B1: Element or value display name | C1: Description | D1: Data type | E1: Character length | F1: Acceptable values | G1: Required? | H1: Accepts null value?
A2: 2013 E Maize Soil VWC | B2: Year | C2: Year | D2: year - yyyy | E2: 4 | G2: Yes | H2: No
A3: 2013 E Maize Soil VWC | B3: DOY | C3: Serial day of the year beginning with 1 for January 1. | D3: integer | E3: 3 | F3: 1 to 366 | G3: Yes | H3: No
A4: 2013 E Maize Soil VWC | B4: Date | C4: Date in yyyy-mm-dd format | D4: date - year/month/day preferably ISO 8601: yyyy-mm-dd | E4: 10 | G4: Yes | H4: No
A5: 2013 E Maize Soil VWC | B5: Time | C5: Time of day in hh:mm format | D5: time: hh:mm | F5: 0 to 24:00 | G5: Yes | H5: Yes, #N/A
A6: 2013 E Maize Soil VWC | B6: Depth in cm | C6: Center depth in cm below the soil surface of soil water content sensing | D6: decimal | G6: Yes | H6: No
A7: 2013 E Maize Soil VWC | B7: Tube no. | C7: Number of the access tube in which the neutron probe was used to sense water content. The tube map gives the relative tube locations in the lysimeters and in the fields surrounding the lysimeters. | D7: integer | F7: 1 to 20 | G7: Yes | H7: No
A8: 2013 E Maize Soil VWC | B8: VWC | C8: Soil volumetric water content. This is a unitless fraction. | D8: decimal | F8: Zero to <1 | G8: Yes | H8: Yes, #N/A
A9: 2013 E Maize Soil VWC | B9: Location | C9: Indicates wether the access tube was in the field, indicated by Fld, or in a lysimeter, indicated by Lys, and what field it was in as indicated by the four intercardinal directions NW, SW, NE, and SE. | D9: varchar(6) | E9: 6 | H9: No

Sheet 2013 E Maize Soil VWC
A1: Year | B1: DOY | C1: Date | D1: Time | E1: Depth in cm | F1: Tube no. | G1: VWC | H1: Location
A2: 2013 | B2: 156 | C2: 41430 | D2: #N/A | E2: 230 | F2: 1 | G2: #N/A | H2: NE Fld
A3: 2013 | B3: 156 | C3: 41430 | D3: #N/A | E3: 230 | F3: 2 | G3: #N/A | H3: NE Fld
A4: 2013 | B4: 156 | C4: 41430 | D4: #N/A | E4: 230 | F4: 3 | G4: #N/A | H4: NE Fld
A5: 2013 | B5: 156 | C5: 41430 | D5: #N/A | E5: 230 | F5: 4 | G5: #N/A | H5: NE Fld
A6: 2013 | B6: 156 | C6: 41430 | D6: 0.48611111 | E6: 230 | F6: 5 | G6: #N/A | H6: NE Lys
A7: 2013 | B7: 156 | C7: 41430 | D7: 0.49097222 | E7: 230 | F7: 6 | G7: #N/A | H7: NE Lys
A8: 2013 | B8: 156 | C8: 41430 | D8: #N/A | E8: 230 | F8: 7 | G8: #N/A | H8: NE Fld
A9: 2013 | B9: 156 | C9: 41430 | D9: #N/A | E9: 230 | F9: 8 | G9: #N/A | H9: NE Fld
A10: 2013 | B10: 156 | C10: 41430 | D10: #N/A | E10: 230 | F10: 9 | G10: #N/A | H10: NE Fld
A11: 2013 | B11: 156 | C11: 41430 | D11: #N/A | E11: 230 | F11: 10 | G11: #N/A | H11: NE Fld
A12: 2013 | B12: 156 | C12: 41430 | D12: #N/A | E12: 230 | F12: 11 | G12: #N/A | H12: SE Fld
A13: 2013 | B13: 156 | C13: 41430 | D13: #N/A | E13: 230 | F13: 12 | G13: #N/A | H13: SE Fld
A14: 2013 | B14: 156 | C14: 41430 | D14: #N/A | E14: 230 | F14: 13 | G14: #N/A | H14: SE Fld
A15: 2013 | B15: 156 | C15: 41430 | D15: #N/A | E15: 230 | F15: 14 | G15: #N/A | H15: SE Fld
A16: 2013 | B16: 156 | C16: 41430 | D16: 0.50486111 | E16: 230 | F16: 15 | G16: #N/A | H16: SE Lys
A17: 2013 | B17: 156 | C17: 41430 | D17: 0.50972222 | E17: 230 | F17: 16 | G17: #N/A | H17: SE Lys
A18: 2013 | B18: 156 | C18: 41430 | D18: #N/A | E18: 230 | F18: 17 | G18: #N/A | H18: SE Fld
A19: 2013 | B19: 156 | C19: 41430 | D19: #N/A | E19: 230 | F19: 18 | G19: #N/A | H19: SE Fld
A20: 2013 | B20: 156 | C20: 41430 | D20: #N/A | E20: 230 | F20: 19 | G20: #N/A | H20: SE Fld
A21: 2013 | B21: 156 | C21: 41430 | D21: #N/A | E21: 230 | F21: 20 | G21: #N/A | H21: SE Fld
A22: 2013 | B22: 156 | C22: 41430 | D22: #N/A | E22: 210 | F22: 1 | G22: #N/A | H22: NE Fld
A23: 2013 | B23: 156 | C23: 41430 | D23: #N/A | E23: 210 | F23: 2 | G23: #N/A | H23: NE Fld
A24: 2013 | B24: 156 | C24: 41430 | D24: #N/A | E24: 210 | F24: 3 | G24: #N/A | H24: NE Fld
A25: 2013 | B25: 156 | C25: 41430 | D25: #N/A | E25: 210 | F25: 4 | G25: #N/A | H25: NE Fld
A26: 2013 | B26: 156 | C26: 41430 | D26: 0.48611111 | E26: 210 | F26: 5 | G26: #N/A | H26: NE Lys
A27: 2013 | B27: 156 | C27: 41430 | D27: 0.49097222 | E27: 210 | F27: 6 | G27: #N/A | H27: NE Lys
A28: 2013 | B28: 156 | C28: 41430 | D28: #N/A | E28: 210 | F28: 7 | G28: #N/A | H28: NE Fld
A29: 2013 | B29: 156 | C29: 41430 | D29: #N/A | E29: 210 | F29: 8 | G29: #N/A | H29: NE Fld
A30: 2013 | B30: 156 | C30: 41430 | D30: #N/A | E30: 210 | F30: 9 | G30: #N/A | H30: NE Fld
A31: 2013 | B31: 156 | C31: 41430 | D31: #N/A | E31: 210 | F31: 10 | G31: #N/A | H31: NE Fld
A32: 2013 | B32: 156 | C32: 41430 | D32: #N/A | E32: 210 | F32: 11 | G32: #N/A | H32: SE Fld
A33: 2013 | B33: 156 | C33: 41430 | D33: #N/A | E33: 210 | F33: 12 | G33: #N/A | H33: SE Fld
A34: 2013 | B34: 156 | C34: 41430 | D34: #N/A | E34: 210 | F34: 13 | G34: #N/A | H34: SE Fld
A35: 2013 | B35: 156 | C35: 41430 | D35: #N/A | E35: 210 | F35: 14 | G35: #N/A | H35: SE Fld
A36: 2013 | B36: 156 | C36: 41430 | D36: 0.50486111 | E36: 210 | F36: 15 | G36: #N/A | H36: SE Lys
A37: 2013 | B37: 156 | C37: 41430 | D37: 0.50972222 | E37: 210 | F37: 16 | G37: #N/A | H37: SE Lys
A38: 2013 | B38: 156 | C38: 41430 | D38: #N/A | E38: 210 | F38: 17 | G38: #N/A | H38: SE Fld
A39: 2013 | B39: 156 | C39: 41430 | D39: #N/A | E39: 210 | F39: 18 | G39: #N/A | H39: SE Fld
A40: 2013 | B40: 156 | C40: 41430 | D40: #N/A | E40: 210 | F40: 19 | G40: #N/A | H40: SE Fld
...

Sheet Dic. 2013 E Maize Tube Map
A1: Spreadsheet tab | B1: Element or value display name | C1: Description | D1: Data type | E1: Character length | F1: Acceptable values | G1: Required? | H1: Accepts null value?
A2: 2013 E Maize Tube Map | B2: Location | C2: Location of the access tube given as in the northeast (NE) field, NE lysimeter (NE Lys), southeast (SE) field, or SE lysimeter (SE Lys); northwest (NW) field, NW lysimeter (NW Lys), southwest (SW) field, or SW lysimeter (SW Lys) | D2: alphanumeric | E2: variable | F2: alphanumeric | G2: Yes | H2: No
A3: 2013 E Maize Tube Map | B3: Tube number | C3: Number of the access tube in which the neutron probe was used to sense water content. | D3: integer | F3: 1 through 20 | G3: Yes | H3: No
A4: 2013 E Maize Tube Map | B4: Latitude | C4: The latitude of the access tube in decimal degress | D4: decimal | G4: Yes | H4: No
A5: 2013 E Maize Tube Map | B5: Longitude | C5: The longitude of the access tube in decimal degrees | D5: decimal | G5: Yes | H5: No

Sheet 2013 E Maize Tube Map
A1: Location | B1: Tube number | C1: latitude | D1: longitude
A2: NE | B2: 1 | C2: 35.188353 | D2: -102.0954
A3: NE | B3: 2 | C3: 35.188353 | D3: -102.09569
A4: NE | B4: 3 | C4: 35.18827 | D4: -102.09569
A5: NE | B5: 4 | C5: 35.18827 | D5: -102.09541
A6: NE Lys | B6: 5 | C6: 35.188173 | D6: -102.09553
A7: NE Lys | B7: 6 | C7: 35.188166 | D7: -102.09555
A8: NE | B8: 7 | C8: 35.188118 | D8: -102.09569
A9: NE | B9: 8 | C9: 35.188118 | D9: -102.0954
A10: NE | B10: 9 | C10: 35.188043 | D10: -102.0954
A11: NE | B11: 10 | C11: 35.188043 | D11: -102.09568
A12: SE | B12: 11 | C12: 35.186281 | D12: -102.09542
A13: SE | B13: 12 | C13: 35.186281 | D13: -102.0957
... A21: SE | B21: 20 | C21: 35.185964 | D21: -102.0957

Sheet 2013 E Maize VWC Graphs
Y1: Depth (cm) | Z1: 230 | AA1: 210 | AB1: 190 | AC1: 170 | AD1: 150 | AE1: 130 | AF1: 110 | AG1: 90 | AH1: 70 | AI1: 50 | AJ1: 30 | AK1: 10 | AW1: Day of year | AX1: Date | AY1: Storage in top 1.5 m of soil in NE Lys | AZ1: Storage in top 1.5 m of soil in NE Field | BA1: Storage in top 1.5 m of soil in SE Lys | BB1: Storage in top 1.5 m of soil in SE Field | BC1: Water stored (mm) in top 2.4 m of NE field tubes 1-2 | BD1: Water stored (mm) in top 2.4 m of NE field tubes 3-4 | BE1: Water stored (mm) in top 2.0 m of NE Lys tubes 5-6 | BF1: Water stored (mm) in top 2.4 m of NE field tubes 7-8 | BG1: Water stored (mm) in top 2.4 m of NE field tubes 9-10 | BH1: Water stored (mm) in top 2.4 m of SE field tubes 11-12 | BI1: Water stored (mm) in top 2.4 m of SE field tubes 13-14 | BJ1: Water stored (mm) in top 2.0 m of SE Lys tubes 15-16 | BK1: Water stored (mm) in top 2.4 m of SE field tubes 17-18 | BL1: Water stored (mm) in top 2.4 m of SE field tubes 19-20 | BM1: Day of year | BN1: Date | BO1: Storage in top 1.5 m of soil in NE Lys | BP1: Storage in top 1.5 m of soil in NE Field | BQ1: Storage in top 1.5 m of soil in SE Lys | BR1: Storage in top 1.5 m of soil in SE Field | BS1: Water stored (mm) in top 2.4 m of NE field tubes 1-2 | BT1: Water stored (mm) in top 2.4 m of NE field tubes 3-4 | BU1: Water stored (mm) in top 2.0 m of NE Lys tubes 5-6 | BV1: Water stored (mm) in top 2.4 m of NE field tubes 7-8 | BW1: Water stored (mm) in top 2.4 m of NE field tubes 9-10 | BX1: Water stored (mm) in top 2.4 m of SE field tubes 11-12 | BY1: Water stored (mm) in top 2.4 m of SE field tubes 13-14 | BZ1: Water stored (mm) in top 2.0 m of SE Lys tubes 15-16 | CA1: Water stored (mm) in top 2.4 m of SE field tubes 17-18 | CB1: Water stored (mm) in top 2.4 m of SE field tubes 19-20
Y2: Porosity (m3/m3) | AA2: 0.46977987 | AB2: 0.4691195 | AC2: 0.45975262 | AD2: 0.46509434 | AE2: 0.42485115 | AF2: 0.41714735 | AG2: 0.44435759 | AH2: 0.45478559 | AI2: 0.43505765 | AJ2: 0.45794811 | AK2: 0.48951842 | BM2: VLOOKUP TABLE
AC3: VWC | AD3: VWC | AE3: VWC | AF3: VWC | AG3: VWC | AH3: VWC | AI3: VWC | AJ3: VWC | AK3: VWC | AL3: VWC | AM3: VWC | AN3: VWC | BM3: Copy columns aw and ax to bm and bn, then sort to eliminate blank lines.
AC4: tube no. | AD4: tube no. | AE4: tube no. | AF4: tube no. | AG4: tube no. | AH4: tube no. | AI4: tube no. | AJ4: tube no. | AK4: tube no. | AL4: tube no. | AM4: tube no. | AN4: tube no. | BM4: VLOOKUP TABLE will find values
Y5: Year | Z5: DOY | AA5: Date | AB5: Depth | AC5: 1 | AD5: 2 | AE5: 3 | AF5: 4 | AG5: 5 | AH5: 6 | AI5: 7 | AJ5: 8 | AK5: 9 | AL5: 10 | AM5: 11 | AN5: 12 | AO5: 13 | AP5: 14 | AQ5: 15 | AR5: 16 | AS5: 17 | AT5: 18 | AU5: 19 | AV5: 20 | BO5: 2 | BP5: 3 | BQ5: 4 | BR5: 5 | BS5: 6 | BT5: 7 | BU5: 8 | BV5: 9 | BW5: 10 | BX5: 11 | BY5: 12 | BZ5: 13 | CA5: 14 | CB5: 15
Y6: 2013 | Z6: 156 | AA6: =DATE(Y6,1,Z6) -> 41430 | AB6: 10 | AC6: {=_xlfn.XLOOKUP(1,('2013 E Maize Soil VWC'!$C$2:$C$4000=$AA6)*('2013 E Maize Soil VWC'!$E$2:$E$4000=$AB6)*('2013 E Maize Soil VWC'!$F$2:$F$4000=AC$5),'2013 E Maize Soil VWC'!$G$2:$G$4000)} -> #N/A | AD6: {=_xlfn.XLOOKUP(1,('2013 E Maize Soil VWC'!$C$2:$C$4000=$AA6)*('2013 E Maize Soil VWC'!$E$2:$E$4000=$AB6)*('2013 E Maize Soil VWC'!$F$2:$F$4000=AD$5),'2013 E Maize Soil VWC'!$G$2:$G$4000)} -> #N/A | AE6: {=_xlfn.XLOOKUP(1,('2013 E Maize Soil VWC'!$C$2:$C$4000=$AA6)*('2013 E Maize Soil VWC'!$E$2:$E$4000=$AB6)*('2013 E Maize Soil VWC'!$F$2:$F$4000=AE$5),'2013 E Maize Soil VWC'!$G$2:$G$4000)} -> #N/A | AF6: {=_xlfn.XLOOKUP(1,('2013 E Maize Soil VWC'!$C$2:$C$4000=$AA6)*('2013 E Maize Soil VWC'!$E$2:$E$4000=$AB6)*('2013 E Maize Soil VWC'!$F$2:$F$4000=AF$5),'2013 E Maize Soil VWC'!$G$2:$G$4000)} -> #N/A | AG6: {=_xlfn.XLOOKUP(1,('2013 E Maize Soil VWC'!$C$2:$C$4000=$AA6)*('2013 E Maize Soil VWC'!$E$2:$E$4000=$AB6)*('2013 E Maize Soil VWC'!$F$2:$F$4000=AG$5),'2013 E Maize Soil VWC'!$G$2:$G$4000)} -> 0.28186999 | AH6: {=_xlfn.XLOOKUP(1,('2013 E Maize Soil VWC'!$C$2:$C$4000=$AA6)*('2013 E Maize Soil VWC'!$E$2:$E$4000=$AB6)*('2013 E Maize Soil VWC'!$F$2:$F$4000=AH$5),'2013 E Maize Soil VWC'!$G$2:$G$4000)} -> 0.26859788 | AI6: {=_xlfn.XLOOKUP(1,('2013 E Maize Soil VWC'!$C$2:$C$4000=$AA6)*('2013 E Maize Soil VWC'!$E$2:$E$4000=$AB6)*('2013 E Maize Soil VWC'!$F$2:$F$4000=AI$5),'2013 E Maize Soil VWC'!$G$2:$G$4000)} -> #N/A | AJ6: {=_xlfn.XLOOKUP(1,('2013 E Maize Soil VWC'!$C$2:$C$4000=$AA6)*('2013 E Maize Soil VWC'!$E$2:$E$4000=$AB6)*('2013 E Maize Soil VWC'!$F$2:$F$4000=AJ$5),'2013 E Maize Soil VWC'!$G$2:$G$4000)} -> #N/A | ... AV6: {=_xlfn.XLOOKUP(1,('2013 E Maize Soil VWC'!$C$2:$C$4000=$AA6)*('2013 E Maize Soil VWC'!$E$2:$E$4000=$AB6)*('2013 E Maize Soil VWC'!$F$2:$F$4000=AV$5),'2013 E Maize Soil VWC'!$G$2:$G$4000)} -> #N/A | AW6: =Z6 -> 156 | AX6: =AA6 -> 41430 | AY6: =1400*AVERAGE(AG6:AH12)+100*AVERAGE(AG13:AH13) -> 506.94172 | AZ6: =1400*AVERAGE(AC6:AF12,AI6:AL12)+100*AVERAGE(AC13:AF13,AI13:AL13) -> #N/A | BA6: =1400*AVERAGE(AQ6:AR12)+100*AVERAGE(AQ13:AR13) -> 495.63484 | BB6: =1400*AVERAGE(AM6:AP12,AS6:AV12)+100*AVERAGE(AM13:AP13,AS13:AV13) -> #N/A | BC6: =AVERAGE(AC6:AD17)*2400 -> #N/A | BD6: =AVERAGE(AE6:AF17)*2400 -> #N/A | BE6: =AVERAGE(AG6:AH15)*2000 -> 672.85676 | BF6: =AVERAGE(AI6:AJ17)*2400 -> #N/A | BG6: =AVERAGE(AK6:AL17)*2400 -> #N/A | BH6: =AVERAGE(AM6:AN17)*2400 -> #N/A | BI6: =AVERAGE(AO6:AP17)*2400 -> #N/A | BJ6: =AVERAGE(AQ6:AR15)*2000 -> 655.79955 | BK6: =AVERAGE(AS6:AT17)*2400 -> #N/A | BL6: =AVERAGE(AU6:AV17)*2400 -> #N/A | BM6: 156 | BN6: 41430 | BO6: =VLOOKUP($BN6,$AX$6:$BL$175,BO$5) -> 506.94172 | BP6: =VLOOKUP($BN6,$AX$6:$BL$175,BP$5) -> #N/A | BQ6: =VLOOKUP($BN6,$AX$6:$BL$175,BQ$5) -> 495.63484 | BR6: =VLOOKUP($BN6,$AX$6:$BL$175,BR$5) -> #N/A | BS6: =VLOOKUP($BN6,$AX$6:$BL$175,BS$5) -> #N/A | BT6: =VLOOKUP($BN6,$AX$6:$BL$175,BT$5) -> #N/A | BU6: =VLOOKUP($BN6,$AX$6:$BL$175,BU$5) -> 672.85676 | BV6: =VLOOKUP($BN6,$AX$6:$BL$175,BV$5) -> #N/A | ... CB6: =VLOOKUP($BN6,$AX$6:$BL$175,CB$5) -> #N/A
AA7: =AA6 -> 41430 | AB7: =AB6+20 -> 30 | AC7: {=_xlfn.XLOOKUP(1,('2013 E Maize Soil VWC'!$C$2:$C$4000=$AA7)*('2013 E Maize Soil VWC'!$E$2:$E$4000=$AB7)*('2013 E Maize Soil VWC'!$F$2:$F$4000=AC$5),'2013 E Maize Soil VWC'!$G$2:$G$4000)} -> #N/A | AD7: {=_xlfn.XLOOKUP(1,('2013 E Maize Soil VWC'!$C$2:$C$4000=$AA7)*('2013 E Maize Soil VWC'!$E$2:$E$4000=$AB7)*('2013 E Maize Soil VWC'!$F$2:$F$4000=AD$5),'2013 E Maize Soil VWC'!$G$2:$G$4000)} -> #N/A | AE7: {=_xlfn.XLOOKUP(1,('2013 E Maize Soil VWC'!$C$2:$C$4000=$AA7)*('2013 E Maize Soil VWC'!$E$2:$E$4000=$AB7)*('2013 E Maize Soil VWC'!$F$2:$F$4000=AE$5),'2013 E Maize Soil VWC'!$G$2:$G$4000)} -> #N/A | AF7: {=_xlfn.XLOOKUP(1,('2013 E Maize Soil VWC'!$C$2:$C$4000=$AA7)*('2013 E Maize Soil VWC'!$E$2:$E$4000=$AB7)*('2013 E Maize Soil VWC'!$F$2:$F$4000=AF$5),'2013 E Maize Soil VWC'!$G$2:$G$4000)} -> #N/A | AG7: {=_xlfn.XLOOKUP(1,('2013 E Maize Soil VWC'!$C$2:$C$4000=$AA7)*('2013 E Maize Soil VWC'!$E$2:$E$4000=$AB7)*('2013 E Maize Soil VWC'!$F$2:$F$4000=AG$5),'2013 E Maize Soil VWC'!$G$2:$G$4000)} -> 0.35414814 | AH7: {=_xlfn.XLOOKUP(1,('2013 E Maize Soil VWC'!$C$2:$C$4000=$AA7)*('2013 E Maize Soil VWC'!$E$2:$E$4000=$AB7)*('2013 E Maize Soil VWC'!$F$2:$F$4000=AH$5),'2013 E Maize Soil VWC'!$G$2:$G$4000)} -> 0.34569651 | AI7: {=_xlfn.XLOOKUP(1,('2013 E Maize Soil VWC'!$C$2:$C$4000=$AA7)*('2013 E Maize Soil VWC'!$E$2:$E$4000=$AB7)*('2013 E Maize Soil VWC'!$F$2:$F$4000=AI$5),'2013 E Maize Soil VWC'!$G$2:$G$4000)} -> #N/A | AJ7: {=_xlfn.XLOOKUP(1,('2013 E Maize Soil VWC'!$C$2:$C$4000=$AA7)*('2013 E Maize Soil VWC'!$E$2:$E$4000=$AB7)*('2013 E Maize Soil VWC'!$F$2:$F$4000=AJ$5),'2013 E Maize Soil VWC'!$G$2:$G$4000)} -> #N/A | ... AV7: {=_xlfn.XLOOKUP(1,('2013 E Maize Soil VWC'!$C$2:$C$4000=$AA7)*('2013 E Maize Soil VWC'!$E$2:$E$4000=$AB7)*('2013 E Maize Soil VWC'!$F$2:$F$4000=AV$5),'2013 E Maize Soil VWC'!$G$2:$G$4000)} -> #N/A | BM7: 157 | BN7: 41431 | BO7: =VLOOKUP($BN7,$AX$6:$BL$175,BO$5) -> 519.51406 | BP7: =VLOOKUP($BN7,$AX$6:$BL$175,BP$5) -> #N/A | BQ7: =VLOOKUP($BN7,$AX$6:$BL$175,BQ$5) -> 508.71275 | BR7: =VLOOKUP($BN7,$AX$6:$BL$175,BR$5) -> #N/A | BS7: =VLOOKUP($BN7,$AX$6:$BL$175,BS$5) -> #N/A | BT7: =VLOOKUP($BN7,$AX$6:$BL$175,BT$5) -> #N/A | BU7: =VLOOKUP($BN7,$AX$6:$BL$175,BU$5) -> 687.2538 | BV7: =VLOOKUP($BN7,$AX$6:$BL$175,BV$5) -> #N/A | ... CB7: =VLOOKUP($BN7,$AX$6:$BL$175,CB$5) -> #N/A
AA8: =AA7 -> 41430 | AB8: =AB7+20 -> 50 | AC8: {=_xlfn.XLOOKUP(1,('2013 E Maize Soil VWC'!$C$2:$C$4000=$AA8)*('2013 E Maize Soil VWC'!$E$2:$E$4000=$AB8)*('2013 E Maize Soil VWC'!$F$2:$F$4000=AC$5),'2013 E Maize Soil VWC'!$G$2:$G$4000)} -> #N/A | AD8: {=_xlfn.XLOOKUP(1,('2013 E Maize Soil VWC'!$C$2:$C$4000=$AA8)*('2013 E Maize Soil VWC'!$E$2:$E$4000=$AB8)*('2013 E Maize Soil VWC'!$F$2:$F$4000=AD$5),'2013 E Maize Soil VWC'!$G$2:$G$4000)} -> #N/A | AE8: {=_xlfn.XLOOKUP(1,('2013 E Maize Soil VWC'!$C$2:$C$4000=$AA8)*('2013 E Maize Soil VWC'!$E$2:$E$4000=$AB8)*('2013 E Maize Soil VWC'!$F$2:$F$4000=AE$5),'2013 E Maize Soil VWC'!$G$2:$G$4000)} -> #N/A | AF8: {=_xlfn.XLOOKUP(1,('2013 E Maize Soil VWC'!$C$2:$C$4000=$AA8)*('2013 E Maize Soil VWC'!$E$2:$E$4000=$AB8)*('2013 E Maize Soil VWC'!$F$2:$F$4000=AF$5),'2013 E Maize Soil VWC'!$G$2:$G$4000)} -> #N/A | AG8: {=_xlfn.XLOOKUP(1,('2013 E Maize Soil VWC'!$C$2:$C$4000=$AA8)*('2013 E Maize Soil VWC'!$E$2:$E$4000=$AB8)*('2013 E Maize Soil VWC'!$F$2:$F$4000=AG$5),'2013 E Maize Soil VWC'!$G$2:$G$4000)} -> 0.36121803 | AH8: {=_xlfn.XLOOKUP(1,('2013 E Maize Soil VWC'!$C$2:$C$4000=$AA8)*('2013 E Maize Soil VWC'!$E$2:$E$4000=$AB8)*('2013 E Maize Soil VWC'!$F$2:$F$4000=AH$5),'2013 E Maize Soil VWC'!$G$2:$G$4000)} -> 0.36253068 | AI8: {=_xlfn.XLOOKUP(1,('2013 E Maize Soil VWC'!$C$2:$C$4000=$AA8)*('2013 E Maize Soil VWC'!$E$2:$E$4000=$AB8)*('2013 E Maize Soil VWC'!$F$2:$F$4000=AI$5),'2013 E Maize Soil VWC'!$G$2:$G$4000)} -> #N/A | AJ8: {=_xlfn.XLOOKUP(1,('2013 E Maize Soil VWC'!$C$2:$C$4000=$AA8)*('2013 E Maize Soil VWC'!$E$2:$E$4000=$AB8)*('2013 E Maize Soil VWC'!$F$2:$F$4000=AJ$5),'2013 E Maize Soil VWC'!$G$2:$G$4000)} -> #N/A | ... AV8: {=_xlfn.XLOOKUP(1,('2013 E Maize Soil VWC'!$C$2:$C$4000=$AA8)*('2013 E Maize Soil VWC'!$E$2:$E$4000=$AB8)*('2013 E Maize Soil VWC'!$F$2:$F$4000=AV$5),'2013 E Maize Soil VWC'!$G$2:$G$4000)} -> #N/A | BM8: 171 | BN8: 41445 | BO8: =VLOOKUP($BN8,$AX$6:$BL$175,BO$5) -> 491.36777 | BP8: =VLOOKUP($BN8,$AX$6:$BL$175,BP$5) -> 498.84464 | BQ8: =VLOOKUP($BN8,$AX$6:$BL$175,BQ$5) -> 477.96338 | BR8: =VLOOKUP($BN8,$AX$6:$BL$175,BR$5) -> 488.92375 | BS8: =VLOOKUP($BN8,$AX$6:$BL$175,BS$5) -> 766.93757 | BT8: =VLOOKUP($BN8,$AX$6:$BL$175,BT$5) -> 751.35444 | BU8: =VLOOKUP($BN8,$AX$6:$BL$175,BU$5) -> 657.68508 | BV8: =VLOOKUP($BN8,$AX$6:$BL$175,BV$5) -> 773.32593 | ... CB8: =VLOOKUP($BN8,$AX$6:$BL$175,CB$5) -> 759.84059
AA9: =AA8 -> 41430 | AB9: =AB8+20 -> 70 | AC9: {=_xlfn.XLOOKUP(1,('2013 E Maize Soil VWC'!$C$2:$C$4000=$AA9)*('2013 E Maize Soil VWC'!$E$2:$E$4000=$AB9)*('2013 E Maize Soil VWC'!$F$2:$F$4000=AC$5),'2013 E Maize Soil VWC'!$G$2:$G$4000)} -> #N/A | AD9: {=_xlfn.XLOOKUP(1,('2013 E Maize Soil VWC'!$C$2:$C$4000=$AA9)*('2013 E Maize Soil VWC'!$E$2:$E$4000=$AB9)*('2013 E Maize Soil VWC'!$F$2:$F$4000=AD$5),'2013 E Maize Soil VWC'!$G$2:$G$4000)} -> #N/A | AE9: {=_xlfn.XLOOKUP(1,('2013 E Maize Soil VWC'!$C$2:$C$4000=$AA9)*('2013 E Maize Soil VWC'!$E$2:$E$4000=$AB9)*('2013 E Maize Soil VWC'!$F$2:$F$4000=AE$5),'2013 E Maize Soil VWC'!$G$2:$G$4000)} -> #N/A | AF9: {=_xlfn.XLOOKUP(1,('2013 E Maize Soil VWC'!$C$2:$C$4000=$AA9)*('2013 E Maize Soil VWC'!$E$2:$E$4000=$AB9)*('2013 E Maize Soil VWC'!$F$2:$F$4000=AF$5),'2013 E Maize Soil VWC'!$G$2:$G$4000)} -> #N/A | AG9: {=_xlfn.XLOOKUP(1,('2013 E Maize Soil VWC'!$C$2:$C$4000=$AA9)*('2013 E Maize Soil VWC'!$E$2:$E$4000=$AB9)*('2013 E Maize Soil VWC'!$F$2:$F$4000=AG$5),'2013 E Maize Soil VWC'!$G$2:$G$4000)} -> 0.36220827 | AH9: {=_xlfn.XLOOKUP(1,('2013 E Maize Soil VWC'!$C$2:$C$4000=$AA9)*('2013 E Maize Soil VWC'!$E$2:$E$4000=$AB9)*('2013 E Maize Soil VWC'!$F$2:$F$4000=AH$5),'2013 E Maize Soil VWC'!$G$2:$G$4000)} -> 0.35472386 | AI9: {=_xlfn.XLOOKUP(1,('2013 E Maize Soil VWC'!$C$2:$C$4000=$AA9)*('2013 E Maize Soil VWC'!$E$2:$E$4000=$AB9)*('2013 E Maize Soil VWC'!$F$2:$F$4000=AI$5),'2013 E Maize Soil VWC'!$G$2:$G$4000)} -> #N/A | AJ9: {=_xlfn.XLOOKUP(1,('2013 E Maize Soil VWC'!$C$2:$C$4000=$AA9)*('2013 E Maize Soil VWC'!$E$2:$E$4000=$AB9)*('2013 E Maize Soil VWC'!$F$2:$F$4000=AJ$5),'2013 E Maize Soil VWC'!$G$2:$G$4000)} -> #N/A | ... AV9: {=_xlfn.XLOOKUP(1,('2013 E Maize Soil VWC'!$C$2:$C$4000=$AA9)*('2013 E Maize Soil VWC'!$E$2:$E$4000=$AB9)*('2013 E Maize Soil VWC'!$F$2:$F$4000=AV$5),'2013 E Maize Soil VWC'!$G$2:$G$4000)} -> #N/A | BM9: 176 | BN9: 41450 | BO9: =VLOOKUP($BN9,$AX$6:$BL$175,BO$5) -> 475.36297 | BP9: =VLOOKUP($BN9,$AX$6:$BL$175,BP$5) -> 488.56182 | BQ9: =VLOOKUP($BN9,$AX$6:$BL$175,BQ$5) -> 460.79909 | BR9: =VLOOKUP($BN9,$AX$6:$BL$175,BR$5) -> 481.37142 | BS9: =VLOOKUP($BN9,$AX$6:$BL$175,BS$5) -> 761.10965 | BT9: =VLOOKUP($BN9,$AX$6:$BL$175,BT$5) -> 743.99529 | BU9: =VLOOKUP($BN9,$AX$6:$BL$175,BU$5) -> 643.6486 | BV9: =VLOOKUP($BN9,$AX$6:$BL$175,BV$5) -> 761.08425 | ... CB9: =VLOOKUP($BN9,$AX$6:$BL$175,CB$5) -> 752.89625
AA10: =AA9 -> 41430 | AB10: =AB9+20 -> 90 | AC10: {=_xlfn.XLOOKUP(1,('2013 E Maize Soil VWC'!$C$2:$C$4000=$AA10)*('2013 E Maize Soil VWC'!$E$2:$E$4000=$AB10)*('2013 E Maize Soil VWC'!$F$2:$F$4000=AC$5),'2013 E Maize Soil VWC'!$G$2:$G$4000)} -> #N/A | AD10: {=_xlfn.XLOOKUP(1,('2013 E Maize Soil VWC'!$C$2:$C$4000=$AA10)*('2013 E Maize Soil VWC'!$E$2:$E$4000=$AB10)*('2013 E Maize Soil VWC'!$F$2:$F$4000=AD$5),'2013 E Maize Soil VWC'!$G$2:$G$4000)} -> #N/A | AE10: {=_xlfn.XLOOKUP(1,('2013 E Maize Soil VWC'!$C$2:$C$4000=$AA10)*('2013 E Maize Soil VWC'!$E$2:$E$4000=$AB10)*('2013 E Maize Soil VWC'!$F$2:$F$4000=AE$5),'2013 E Maize Soil VWC'!$G$2:$G$4000)} -> #N/A | AF10: {=_xlfn.XLOOKUP(1,('2013 E Maize Soil VWC'!$C$2:$C$4000=$AA10)*('2013 E Maize Soil VWC'!$E$2:$E$4000=$AB10)*('2013 E Maize Soil VWC'!$F$2:$F$4000=AF$5),'2013 E Maize Soil VWC'!$G$2:$G$4000)} -> #N/A | AG10: {=_xlfn.XLOOKUP(1,('2013 E Maize Soil VWC'!$C$2:$C$4000=$AA10)*('2013 E Maize Soil VWC'!$E$2:$E$4000=$AB10)*('2013 E Maize Soil VWC'!$F$2:$F$4000=AG$5),'2013 E Maize Soil VWC'!$G$2:$G$4000)} -> 0.35221371 | AH10: {=_xlfn.XLOOKUP(1,('2013 E Maize Soil VWC'!$C$2:$C$4000=$AA10)*('2013 E Maize Soil VWC'!$E$2:$E$4000=$AB10)*('2013 E Maize Soil VWC'!$F$2:$F$4000=AH$5),'2013 E Maize Soil VWC'!$G$2:$G$4000)} -> 0.34546622 | AI10: {=_xlfn.XLOOKUP(1,('2013 E Maize Soil VWC'!$C$2:$C$4000=$AA10)*('2013 E Maize Soil VWC'!$E$2:$E$4000=$AB10)*('2013 E Maize Soil VWC'!$F$2:$F$4000=AI$5),'2013 E Maize Soil VWC'!$G$2:$G$4000)} -> #N/A | AJ10: {=_xlfn.XLOOKUP(1,('2013 E Maize Soil VWC'!$C$2:$C$4000=$AA10)*('2013 E Maize Soil VWC'!$E$2:$E$4000=$AB10)*('2013 E Maize Soil VWC'!$F$2:$F$4000=AJ$5),'2013 E Maize Soil VWC'!$G$2:$G$4000)} -> #N/A | ... AV10: {=_xlfn.XLOOKUP(1,('2013 E Maize Soil VWC'!$C$2:$C$4000=$AA10)*('2013 E Maize Soil VWC'!$E$2:$E$4000=$AB10)*('2013 E Maize Soil VWC'!$F$2:$F$4000=AV$5),'2013 E Maize Soil VWC'!$G$2:$G$4000)} -> #N/A | BM10: 183 | BN10: 41457 | BO10: =VLOOKUP($BN10,$AX$6:$BL$175,BO$5) -> 456.07393 | BP10: =VLOOKUP($BN10,$AX$6:$BL$175,BP$5) -> 480.07498 | BQ10: =VLOOKUP($BN10,$AX$6:$BL$175,BQ$5) -> 444.1267 | BR10: =VLOOKUP($BN10,$AX$6:$BL$175,BR$5) -> 464.43469 | BS10: =VLOOKUP($BN10,$AX$6:$BL$175,BS$5) -> 743.27934 | BT10: =VLOOKUP($BN10,$AX$6:$BL$175,BT$5) -> 729.86029 | BU10: =VLOOKUP($BN10,$AX$6:$BL$175,BU$5) -> 623.86235 | BV10: =VLOOKUP($BN10,$AX$6:$BL$175,BV$5) -> 761.91323 | ... CB10: =VLOOKUP($BN10,$AX$6:$BL$175,CB$5) -> 738.92724
AA11: =AA10 -> 41430 | AB11: =AB10+20 -> 110 | AC11: {=_xlfn.XLOOKUP(1,('2013 E Maize Soil VWC'!$C$2:$C$4000=$AA11)*('2013 E Maize Soil VWC'!$E$2:$E$4000=$AB11)*('2013 E Maize Soil VWC'!$F$2:$F$4000=AC$5),'2013 E Maize Soil VWC'!$G$2:$G$4000)} -> #N/A | AD11: {=_xlfn.XLOOKUP(1,('2013 E Maize Soil VWC'!$C$2:$C$4000=$AA11)*('2013 E Maize Soil VWC'!$E$2:$E$4000=$AB11)*('2013 E Maize Soil VWC'!$F$2:$F$4000=AD$5),'2013 E Maize Soil VWC'!$G$2:$G$4000)} -> #N/A | AE11: {=_xlfn.XLOOKUP(1,('2013 E Maize Soil VWC'!$C$2:$C$4000=$AA11)*('2013 E Maize Soil VWC'!$E$2:$E$4000=$AB11)*('2013 E Maize Soil VWC'!$F$2:$F$4000=AE$5),'2013 E Maize Soil VWC'!$G$2:$G$4000)} -> #N/A | AF11: {=_xlfn.XLOOKUP(1,('2013 E Maize Soil VWC'!$C$2:$C$4000=$AA11)*('2013 E Maize Soil VWC'!$E$2:$E$4000=$AB11)*('2013 E Maize Soil VWC'!$F$2:$F$4000=AF$5),'2013 E Maize Soil VWC'!$G$2:$G$4000)} -> #N/A | AG11: {=_xlfn.XLOOKUP(1,('2013 E Maize Soil VWC'!$C$2:$C$4000=$AA11)*('2013 E Maize Soil VWC'!$E$2:$E$4000=$AB11)*('2013 E Maize Soil VWC'!$F$2:$F$4000=AG$5),'2013 E Maize Soil VWC'!$G$2:$G$4000)} -> 0.349266 | AH11: {=_xlfn.XLOOKUP(1,('2013 E Maize Soil VWC'!$C$2:$C$4000=$AA11)*('2013 E Maize Soil VWC'!$E$2:$E$4000=$AB11)*('2013 E Maize Soil VWC'!$F$2:$F$4000=AH$5),'2013 E Maize Soil VWC'!$G$2:$G$4000)} -> 0.34058408 | AI11: {=_xlfn.XLOOKUP(1,('2013 E Maize Soil VWC'!$C$2:$C$4000=$AA11)*('2013 E Maize Soil VWC'!$E$2:$E$4000=$AB11)*('2013 E Maize Soil VWC'!$F$2:$F$4000=AI$5),'2013 E Maize Soil VWC'!$G$2:$G$4000)} -> #N/A | AJ11: {=_xlfn.XLOOKUP(1,('2013 E Maize Soil VWC'!$C$2:$C$4000=$AA11)*('2013 E Maize Soil VWC'!$E$2:$E$4000=$AB11)*('2013 E Maize Soil VWC'!$F$2:$F$4000=AJ$5),'2013 E Maize Soil VWC'!$G$2:$G$4000)} -> #N/A | ... AV11: {=_xlfn.XLOOKUP(1,('2013 E Maize Soil VWC'!$C$2:$C$4000=$AA11)*('2013 E Maize Soil VWC'!$E$2:$E$4000=$AB11)*('2013 E Maize Soil VWC'!$F$2:$F$4000=AV$5),'2013 E Maize Soil VWC'!$G$2:$G$4000)} -> #N/A | BM11: 189 | BN11: 41463 | BO11: =VLOOKUP($BN11,$AX$6:$BL$175,BO$5) -> 459.89126 | BP11: =VLOOKUP($BN11,$AX$6:$BL$175,BP$5) -> 493.56863 | BQ11: =VLOOKUP($BN11,$AX$6:$BL$175,BQ$5) -> 443.71051 | BR11: =VLOOKUP($BN11,$AX$6:$BL$175,BR$5) -> 479.82985 | BS11: =VLOOKUP($BN11,$AX$6:$BL$175,BS$5) -> 760.8071 | BT11: =VLOOKUP($BN11,$AX$6:$BL$175,BT$5) -> 747.56899 | BU11: =VLOOKUP($BN11,$AX$6:$BL$175,BU$5) -> 628.91978 | BV11: =VLOOKUP($BN11,$AX$6:$BL$175,BV$5) -> 776.75582 | ... CB11: =VLOOKUP($BN11,$AX$6:$BL$175,CB$5) -> 752.56223
AA12: =AA11 -> 41430 | AB12: =AB11+20 -> 130 | AC12: {=_xlfn.XLOOKUP(1,('2013 E Maize Soil VWC'!$C$2:$C$4000=$AA12)*('2013 E Maize Soil VWC'!$E$2:$E$4000=$AB12)*('2013 E Maize Soil VWC'!$F$2:$F$4000=AC$5),'2013 E Maize Soil VWC'!$G$2:$G$4000)} -> #N/A | AD12: {=_xlfn.XLOOKUP(1,('2013 E Maize Soil VWC'!$C$2:$C$4000=$AA12)*('2013 E Maize Soil VWC'!$E$2:$E$4000=$AB12)*('2013 E Maize Soil VWC'!$F$2:$F$4000=AD$5),'2013 E Maize Soil VWC'!$G$2:$G$4000)} -> #N/A | AE12: {=_xlfn.XLOOKUP(1,('2013 E Maize Soil VWC'!$C$2:$C$4000=$AA12)*('2013 E Maize Soil VWC'!$E$2:$E$4000=$AB12)*('2013 E Maize Soil VWC'!$F$2:$F$4000=AE$5),'2013 E Maize Soil VWC'!$G$2:$G$4000)} -> #N/A | AF12: {=_xlfn.XLOOKUP(1,('2013 E Maize Soil VWC'!$C$2:$C$4000=$AA12)*('2013 E Maize Soil VWC'!$E$2:$E$4000=$AB12)*('2013 E Maize Soil VWC'!$F$2:$F$4000=AF$5),'2013 E Maize Soil VWC'!$G$2:$G$4000)} -> #N/A | AG12: {=_xlfn.XLOOKUP(1,('2013 E Maize Soil VWC'!$C$2:$C$4000=$AA12)*('2013 E Maize Soil VWC'!$E$2:$E$4000=$AB12)*('2013 E Maize Soil VWC'!$F$2:$F$4000=AG$5),'2013 E Maize Soil VWC'!$G$2:$G$4000)} -> 0.32060152 | AH12: {=_xlfn.XLOOKUP(1,('2013 E Maize Soil VWC'!$C$2:$C$4000=$AA12)*('2013 E Maize Soil VWC'!$E$2:$E$4000=$AB12)*('2013 E Maize Soil VWC'!$F$2:$F$4000=AH$5),'2013 E Maize Soil VWC'!$G$2:$G$4000)} -> 0.31314323 | AI12: {=_xlfn.XLOOKUP(1,('2013 E Maize Soil VWC'!$C$2:$C$4000=$AA12)*('2013 E Maize Soil VWC'!$E$2:$E$4000=$AB12)*('2013 E Maize Soil VWC'!$F$2:$F$4000=AI$5),'2013 E Maize Soil VWC'!$G$2:$G$4000)} -> #N/A | AJ12: {=_xlfn.XLOOKUP(1,('2013 E Maize Soil VWC'!$C$2:$C$4000=$AA12)*('2013 E Maize Soil VWC'!$E$2:$E$4000=$AB12)*('2013 E Maize Soil VWC'!$F$2:$F$4000=AJ$5),'2013 E Maize Soil VWC'!$G$2:$G$4000)} -> #N/A | ... AV12: {=_xlfn.XLOOKUP(1,('2013 E Maize Soil VWC'!$C$2:$C$4000=$AA12)*('2013 E Maize Soil VWC'!$E$2:$E$4000=$AB12)*('2013 E Maize Soil VWC'!$F$2:$F$4000=AV$5),'2013 E Maize Soil VWC'!$G$2:$G$4000)} -> #N/A | BM12: 197 | BN12: 41471 | BO12: =VLOOKUP($BN12,$AX$6:$BL$175,BO$5) -> 445.79682 | BP12: =VLOOKUP($BN12,$AX$6:$BL$175,BP$5) -> 485.09249 | BQ12: =VLOOKUP($BN12,$AX$6:$BL$175,BQ$5) -> 433.5371 | BR12: =VLOOKUP($BN12,$AX$6:$BL$175,BR$5) -> #N/A | BS12: =VLOOKUP($BN12,$AX$6:$BL$175,BS$5) -> 761.23588 | BT12: =VLOOKUP($BN12,$AX$6:$BL$175,BT$5) -> 730.68937 | BU12: =VLOOKUP($BN12,$AX$6:$BL$175,BU$5) -> 612.812 | BV12: =VLOOKUP($BN12,$AX$6:$BL$175,BV$5) -> 767.78707 | ... CB12: =VLOOKUP($BN12,$AX$6:$BL$175,CB$5) -> #N/A
AA13: =AA12 -> 41430 | AB13: =AB12+20 -> 150 | AC13: {=_xlfn.XLOOKUP(1,('2013 E Maize Soil VWC'!$C$2:$C$4000=$AA13)*('2013 E Maize Soil VWC'!$E$2:$E$4000=$AB13)*('2013 E Maize Soil VWC'!$F$2:$F$4000=AC$5),'2013 E Maize Soil VWC'!$G$2:$G$4000)} -> #N/A | AD13: {=_xlfn.XLOOKUP(1,('2013 E Maize Soil VWC'!$C$2:$C$4000=$AA13)*('2013 E Maize Soil VWC'!$E$2:$E$4000=$AB13)*('2013 E Maize Soil VWC'!$F$2:$F$4000=AD$5),'2013 E Maize Soil VWC'!$G$2:$G$4000)} -> #N/A | AE13: {=_xlfn.XLOOKUP(1,('2013 E Maize Soil VWC'!$C$2:$C$4000=$AA13)*('2013 E Maize Soil VWC'!$E$2:$E$4000=$AB13)*('2013 E Maize Soil VWC'!$F$2:$F$4000=AE$5),'2013 E Maize Soil VWC'!$G$2:$G$4000)} -> #N/A | AF13: {=_xlfn.XLOOKUP(1,('2013 E Maize Soil VWC'!$C$2:$C$4000=$AA13)*('2013 E Maize Soil VWC'!$E$2:$E$4000=$AB13)*('2013 E Maize Soil VWC'!$F$2:$F$4000=AF$5),'2013 E Maize Soil VWC'!$G$2:$G$4000)} -> #N/A | AG13: {=_xlfn.XLOOKUP(1,('2013 E Maize Soil VWC'!$C$2:$C$4000=$AA13)*('2013 E Maize Soil VWC'!$E$2:$E$4000=$AB13)*('2013 E Maize Soil VWC'!$F$2:$F$4000=AG$5),'2013 E Maize Soil VWC'!$G$2:$G$4000)} -> 0.36339371 | AH13: {=_xlfn.XLOOKUP(1,('2013 E Maize Soil VWC'!$C$2:$C$4000=$AA13)*('2013 E Maize Soil VWC'!$E$2:$E$4000=$AB13)*('2013 E Maize Soil VWC'!$F$2:$F$4000=AH$5),'2013 E Maize Soil VWC'!$G$2:$G$4000)} -> 0.3509045 | AI13: {=_xlfn.XLOOKUP(1,('2013 E Maize Soil VWC'!$C$2:$C$4000=$AA13)*('2013 E Maize Soil VWC'!$E$2:$E$4000=$AB13)*('2013 E Maize Soil VWC'!$F$2:$F$4000=AI$5),'2013 E Maize Soil VWC'!$G$2:$G$4000)} -> #N/A | AJ13: {=_xlfn.XLOOKUP(1,('2013 E Maize Soil VWC'!$C$2:$C$4000=$AA13)*('2013 E Maize Soil VWC'!$E$2:$E$4000=$AB13)*('2013 E Maize Soil VWC'!$F$2:$F$4000=AJ$5),'2013 E Maize Soil VWC'!$G$2:$G$4000)} -> #N/A | ... AV13: {=_xlfn.XLOOKUP(1,('2013 E Maize Soil VWC'!$C$2:$C$4000=$AA13)*('2013 E Maize Soil VWC'!$E$2:$E$4000=$AB13)*('2013 E Maize Soil VWC'!$F$2:$F$4000=AV$5),'2013 E Maize Soil VWC'!$G$2:$G$4000)} -> #N/A | BM13: 203 | BN13: 41477 | BO13: =VLOOKUP($BN13,$AX$6:$BL$175,BO$5) -> 487.84113 | BP13: =VLOOKUP($BN13,$AX$6:$BL$175,BP$5) -> 502.7873 | BQ13: =VLOOKUP($BN13,$AX$6:$BL$175,BQ$5) -> 469.98712 | BR13: =VLOOKUP($BN13,$AX$6:$BL$175,BR$5) -> 488.64634 | BS13: =VLOOKUP($BN13,$AX$6:$BL$175,BS$5) -> 768.47153 | BT13: =VLOOKUP($BN13,$AX$6:$BL$175,BT$5) -> 759.84676 | BU13: =VLOOKUP($BN13,$AX$6:$BL$175,BU$5) -> 657.18776 | BV13: =VLOOKUP($BN13,$AX$6:$BL$175,BV$5) -> 779.4726 | ... CB13: =VLOOKUP($BN13,$AX$6:$BL$175,CB$5) -> 760.16217
AA14: =AA13 -> 41430 | AB14: =AB13+20 -> 170 | AC14: {=_xlfn.XLOOKUP(1,('2013 E Maize Soil VWC'!$C$2:$C$4000=$AA14)*('2013 E Maize Soil VWC'!$E$2:$E$4000=$AB14)*('2013 E Maize Soil VWC'!$F$2:$F$4000=AC$5),'2013 E Maize Soil VWC'!$G$2:$G$4000)} -> #N/A | AD14: {=_xlfn.XLOOKUP(1,('2013 E Maize Soil VWC'!$C$2:$C$4000=$AA14)*('2013 E Maize Soil VWC'!$E$2:$E$4000=$AB14)*('2013 E Maize Soil VWC'!$F$2:$F$4000=AD$5),'2013 E Maize Soil VWC'!$G$2:$G$4000)} -> #N/A | AE14: {=_xlfn.XLOOKUP(1,('2013 E Maize Soil VWC'!$C$2:$C$4000=$AA14)*('2013 E Maize Soil VWC'!$E$2:$E$4000=$AB14)*('2013 E Maize Soil VWC'!$F$2:$F$4000=AE$5),'2013 E Maize Soil VWC'!$G$2:$G$4000)} -> #N/A | AF14: {=_xlfn.XLOOKUP(1,('2013 E Maize Soil VWC'!$C$2:$C$4000=$AA14)*('2013 E Maize Soil VWC'!$E$2:$E$4000=$AB14)*('2013 E Maize Soil VWC'!$F$2:$F$4000=AF$5),'2013 E Maize Soil VWC'!$G$2:$G$4000)} -> #N/A | AG14: {=_xlfn.XLOOKUP(1,('2013 E Maize Soil VWC'!$C$2:$C$4000=$AA14)*('2013 E Maize Soil VWC'!$E$2:$E$4000=$AB14)*('2013 E Maize Soil VWC'!$F$2:$F$4000=AG$5),'2013 E Maize Soil VWC'!$G$2:$G$4000)} -> 0.32506475 | AH14: {=_xlfn.XLOOKUP(1,('2013 E Maize Soil VWC'!$C$2:$C$4000=$AA14)*('2013 E Maize Soil VWC'!$E$2:$E$4000=$AB14)*('2013 E Maize Soil VWC'!$F$2:$F$4000=AH$5),'2013 E Maize Soil VWC'!$G$2:$G$4000)} -> 0.32340083 | AI14: {=_xlfn.XLOOKUP(1,('2013 E Maize Soil VWC'!$C$2:$C$4000=$AA14)*('2013 E Maize Soil VWC'!$E$2:$E$4000=$AB14)*('2013 E Maize Soil VWC'!$F$2:$F$4000=AI$5),'2013 E Maize Soil VWC'!$G$2:$G$4000)} -> #N/A | AJ14: {=_xlfn.XLOOKUP(1,('2013 E Maize Soil VWC'!$C$2:$C$4000=$AA14)*('2013 E Maize Soil VWC'!$E$2:$E$4000=$AB14)*('2013 E Maize Soil VWC'!$F$2:$F$4000=AJ$5),'2013 E Maize Soil VWC'!$G$2:$G$4000)} -> #N/A | ... AV14: {=_xlfn.XLOOKUP(1,('2013 E Maize Soil VWC'!$C$2:$C$4000=$AA14)*('2013 E Maize Soil VWC'!$E$2:$E$4000=$AB14)*('2013 E Maize Soil VWC'!$F$2:$F$4000=AV$5),'2013 E Maize Soil VWC'!$G$2:$G$4000)} -> #N/A | BM14: 210 | BN14: 41484 | BO14: =VLOOKUP($BN14,$AX$6:$BL$175,BO$5) -> 441.97995 | BP14: =VLOOKUP($BN14,$AX$6:$BL$175,BP$5) -> 462.97863 | BQ14: =VLOOKUP($BN14,$AX$6:$BL$175,BQ$5) -> 418.34027 | BR14: =VLOOKUP($BN14,$AX$6:$BL$175,BR$5) -> 446.608 | BS14: =VLOOKUP($BN14,$AX$6:$BL$175,BS$5) -> 724.72467 | BT14: =VLOOKUP($BN14,$AX$6:$BL$175,BT$5) -> 717.3211 | BU14: =VLOOKUP($BN14,$AX$6:$BL$175,BU$5) -> 610.19119 | BV14: =VLOOKUP($BN14,$AX$6:$BL$175,BV$5) -> 739.96747 | ... CB14: =VLOOKUP($BN14,$AX$6:$BL$175,CB$5) -> 722.48533
AA15: =AA14 -> 41430 | AB15: =AB14+20 -> 190 | AC15: {=_xlfn.XLOOKUP(1,('2013 E Maize Soil VWC'!$C$2:$C$4000=$AA15)*('2013 E Maize Soil VWC'!$E$2:$E$4000=$AB15)*('2013 E Maize Soil VWC'!$F$2:$F$4000=AC$5),'2013 E Maize Soil VWC'!$G$2:$G$4000)} -> #N/A | AD15: {=_xlfn.XLOOKUP(1,('2013 E Maize Soil VWC'!$C$2:$C$4000=$AA15)*('2013 E Maize Soil VWC'!$E$2:$E$4000=$AB15)*('2013 E Maize Soil VWC'!$F$2:$F$4000=AD$5),'2013 E Maize Soil VWC'!$G$2:$G$4000)} -> #N/A | AE15: {=_xlfn.XLOOKUP(1,('2013 E Maize Soil VWC'!$C$2:$C$4000=$AA15)*('2013 E Maize Soil VWC'!$E$2:$E$4000=$AB15)*('2013 E Maize Soil VWC'!$F$2:$F$4000=AE$5),'2013 E Maize Soil VWC'!$G$2:$G$4000)} -> #N/A | AF15: {=_xlfn.XLOOKUP(1,('2013 E Maize Soil VWC'!$C$2:$C$4000=$AA15)*('2013 E Maize Soil VWC'!$E$2:$E$4000=$AB15)*('2013 E Maize Soil VWC'!$F$2:$F$4000=AF$5),'2013 E Maize Soil VWC'!$G$2:$G$4000)} -> #N/A | AG15: {=_xlfn.XLOOKUP(1,('2013 E Maize Soil VWC'!$C$2:$C$4000=$AA15)*('2013 E Maize Soil VWC'!$E$2:$E$4000=$AB15)*('2013 E Maize Soil VWC'!$F$2:$F$4000=AG$5),'2013 E Maize Soil VWC'!$G$2:$G$4000)} -> 0.32060152 | AH15: {=_xlfn.XLOOKUP(1,('2013 E Maize Soil VWC'!$C$2:$C$4000=$AA15)*('2013 E Maize Soil VWC'!$E$2:$E$4000=$AB15)*('2013 E Maize Soil VWC'!$F$2:$F$4000=AH$5),'2013 E Maize Soil VWC'!$G$2:$G$4000)} -> 0.33293413 | AI15: {=_xlfn.XLOOKUP(1,('2013 E Maize Soil VWC'!$C$2:$C$4000=$AA15)*('2013 E Maize Soil VWC'!$E$2:$E$4000=$AB15)*('2013 E Maize Soil VWC'!$F$2:$F$4000=AI$5),'2013 E Maize Soil VWC'!$G$2:$G$4000)} -> #N/A | AJ15: {=_xlfn.XLOOKUP(1,('2013 E Maize Soil VWC'!$C$2:$C$4000=$AA15)*('2013 E Maize Soil VWC'!$E$2:$E$4000=$AB15)*('2013 E Maize Soil VWC'!$F$2:$F$4000=AJ$5),'2013 E Maize Soil VWC'!$G$2:$G$4000)} -> #N/A | ... AV15: {=_xlfn.XLOOKUP(1,('2013 E Maize Soil VWC'!$C$2:$C$4000=$AA15)*('2013 E Maize Soil VWC'!$E$2:$E$4000=$AB15)*('2013 E Maize Soil VWC'!$F$2:$F$4000=AV$5),'2013 E Maize Soil VWC'!$G$2:$G$4000)} -> #N/A | BM15: 218 | BN15: 41492 | BO15: =VLOOKUP($BN15,$AX$6:$BL$175,BO$5) -> 437.10029 | BP15: =VLOOKUP($BN15,$AX$6:$BL$175,BP$5) -> 457.46316 | BQ15: =VLOOKUP($BN15,$AX$6:$BL$175,BQ$5) -> 419.73272 | BR15: =VLOOKUP($BN15,$AX$6:$BL$175,BR$5) -> 446.92444 | BS15: =VLOOKUP($BN15,$AX$6:$BL$175,BS$5) -> 723.8507 | BT15: =VLOOKUP($BN15,$AX$6:$BL$175,BT$5) -> 706.33722 | BU15: =VLOOKUP($BN15,$AX$6:$BL$175,BU$5) -> 603.24044 | BV15: =VLOOKUP($BN15,$AX$6:$BL$175,BV$5) -> 731.67619 | ... CB15: =VLOOKUP($BN15,$AX$6:$BL$175,CB$5) -> 720.58663
AA16: =AA15 -> 41430 | AB16: =AB15+20 -> 210 | AC16: {=_xlfn.XLOOKUP(1,('2013 E Maize Soil VWC'!$C$2:$C$4000=$AA16)*('2013 E Maize Soil VWC'!$E$2:$E$4000=$AB16)*('2013 E Maize Soil VWC'!$F$2:$F$4000=AC$5),'2013 E Maize Soil VWC'!$G$2:$G$4000)} -> #N/A | AD16: {=_xlfn.XLOOKUP(1,('2013 E Maize Soil VWC'!$C$2:$C$4000=$AA16)*('2013 E Maize Soil VWC'!$E$2:$E$4000=$AB16)*('2013 E Maize Soil VWC'!$F$2:$F$4000=AD$5),'2013 E Maize Soil VWC'!$G$2:$G$4000)} -> #N/A | AE16: {=_xlfn.XLOOKUP(1,('2013 E Maize Soil VWC'!$C$2:$C$4000=$AA16)*('2013 E Maize Soil VWC'!$E$2:$E$4000=$AB16)*('2013 E Maize Soil VWC'!$F$2:$F$4000=AE$5),'2013 E Maize Soil VWC'!$G$2:$G$4000)} -> #N/A | AF16: {=_xlfn.XLOOKUP(1,('2013 E Maize Soil VWC'!$C$2:$C$4000=$AA16)*('2013 E Maize Soil VWC'!$E$2:$E$4000=$AB16)*('2013 E Maize Soil VWC'!$F$2:$F$4000=AF$5),'2013 E Maize Soil VWC'!$G$2:$G$4000)} -> #N/A | AG16: {=_xlfn.XLOOKUP(1,('2013 E Maize Soil VWC'!$C$2:$C$4000=$AA16)*('2013 E Maize Soil VWC'!$E$2:$E$4000=$AB16)*('2013 E Maize Soil VWC'!$F$2:$F$4000=AG$5),'2013 E Maize Soil VWC'!$G$2:$G$4000)} -> #N/A | AH16: {=_xlfn.XLOOKUP(1,('2013 E Maize Soil VWC'!$C$2:$C$4000=$AA16)*('2013 E Maize Soil VWC'!$E$2:$E$4000=$AB16)*('2013 E Maize Soil VWC'!$F$2:$F$4000=AH$5),'2013 E Maize Soil VWC'!$G$2:$G$4000)} -> #N/A | AI16: {=_xlfn.XLOOKUP(1,('2013 E Maize Soil VWC'!$C$2:$C$4000=$AA16)*('2013 E Maize Soil VWC'!$E$2:$E$4000=$AB16)*('2013 E Maize Soil VWC'!$F$2:$F$4000=AI$5),'2013 E Maize Soil VWC'!$G$2:$G$4000)} -> #N/A | AJ16: {=_xlfn.XLOOKUP(1,('2013 E Maize Soil VWC'!$C$2:$C$4000=$AA16)*('2013 E Maize Soil VWC'!$E$2:$E$4000=$AB16)*('2013 E Maize Soil VWC'!$F$2:$F$4000=AJ$5),'2013 E Maize Soil VWC'!$G$2:$G$4000)} -> #N/A | ... AV16: {=_xlfn.XLOOKUP(1,('2013 E Maize Soil VWC'!$C$2:$C$4000=$AA16)*('2013 E Maize Soil VWC'!$E$2:$E$4000=$AB16)*('2013 E Maize Soil VWC'!$F$2:$F$4000=AV$5),'2013 E Maize Soil VWC'!$G$2:$G$4000)} -> #N/A | BM16: 231 | BN16: 41505 | BO16: =VLOOKUP($BN16,$AX$6:$BL$175,BO$5) -> 480.21012 | BP16: =VLOOKUP($BN16,$AX$6:$BL$175,BP$5) -> 482.14194 | BQ16: =VLOOKUP($BN16,$AX$6:$BL$175,BQ$5) -> 458.69814 | BR16: =VLOOKUP($BN16,$AX$6:$BL$175,BR$5) -> 473.03769 | BS16: =VLOOKUP($BN16,$AX$6:$BL$175,BS$5) -> 747.06675 | BT16: =VLOOKUP($BN16,$AX$6:$BL$175,BT$5) -> 730.57817 | BU16: =VLOOKUP($BN16,$AX$6:$BL$175,BU$5) -> 647.06185 | BV16: =VLOOKUP($BN16,$AX$6:$BL$175,BV$5) -> 750.85049 | ... CB16: =VLOOKUP($BN16,$AX$6:$BL$175,CB$5) -> 741.40886
AA17: =AA16 -> 41430 | AB17: =AB16+20 -> 230 | AC17: {=_xlfn.XLOOKUP(1,('2013 E Maize Soil VWC'!$C$2:$C$4000=$AA17)*('2013 E Maize Soil VWC'!$E$2:$E$4000=$AB17)*('2013 E Maize Soil VWC'!$F$2:$F$4000=AC$5),'2013 E Maize Soil VWC'!$G$2:$G$4000)} -> #N/A | AD17: {=_xlfn.XLOOKUP(1,('2013 E Maize Soil VWC'!$C$2:$C$4000=$AA17)*('2013 E Maize Soil VWC'!$E$2:$E$4000=$AB17)*('2013 E Maize Soil VWC'!$F$2:$F$4000=AD$5),'2013 E Maize Soil VWC'!$G$2:$G$4000)} -> #N/A | AE17: {=_xlfn.XLOOKUP(1,('2013 E Maize Soil VWC'!$C$2:$C$4000=$AA17)*('2013 E Maize Soil VWC'!$E$2:$E$4000=$AB17)*('2013 E Maize Soil VWC'!$F$2:$F$4000=AE$5),'2013 E Maize Soil VWC'!$G$2:$G$4000)} -> #N/A | AF17: {=_xlfn.XLOOKUP(1,('2013 E Maize Soil VWC'!$C$2:$C$4000=$AA17)*('2013 E Maize Soil VWC'!$E$2:$E$4000=$AB17)*('2013 E Maize Soil VWC'!$F$2:$F$4000=AF$5),'2013 E Maize Soil VWC'!$G$2:$G$4000)} -> #N/A | AG17: {=_xlfn.XLOOKUP(1,('2013 E Maize Soil VWC'!$C$2:$C$4000=$AA17)*('2013 E Maize Soil VWC'!$E$2:$E$4000=$AB17)*('2013 E Maize Soil VWC'!$F$2:$F$4000=AG$5),'2013 E Maize Soil VWC'!$G$2:$G$4000)} -> #N/A | AH17: {=_xlfn.XLOOKUP(1,('2013 E Maize Soil VWC'!$C$2:$C$4000=$AA17)*('2013 E Maize Soil VWC'!$E$2:$E$4000=$AB17)*('2013 E Maize Soil VWC'!$F$2:$F$4000=AH$5),'2013 E Maize Soil VWC'!$G$2:$G$4000)} -> #N/A | AI17: {=_xlfn.XLOOKUP(1,('2013 E Maize Soil VWC'!$C$2:$C$4000=$AA17)*('2013 E Maize Soil VWC'!$E$2:$E$4000=$AB17)*('2013 E Maize Soil VWC'!$F$2:$F$4000=AI$5),'2013 E Maize Soil VWC'!$G$2:$G$4000)} -> #N/A | AJ17: {=_xlfn.XLOOKUP(1,('2013 E Maize Soil VWC'!$C$2:$C$4000=$AA17)*('2013 E Maize Soil VWC'!$E$2:$E$4000=$AB17)*('2013 E Maize Soil VWC'!$F$2:$F$4000=AJ$5),'2013 E Maize Soil VWC'!$G$2:$G$4000)} -> #N/A | ... AV17: {=_xlfn.XLOOKUP(1,('2013 E Maize Soil VWC'!$C$2:$C$4000=$AA17)*('2013 E Maize Soil VWC'!$E$2:$E$4000=$AB17)*('2013 E Maize Soil VWC'!$F$2:$F$4000=AV$5),'2013 E Maize Soil VWC'!$G$2:$G$4000)} -> #N/A | BM17: 246 | BN17: 41520 | BO17: =VLOOKUP($BN17,$AX$6:$BL$175,BO$5) -> 439.53013 | BP17: =VLOOKUP($BN17,$AX$6:$BL$175,BP$5) -> 432.73597 | BQ17: =VLOOKUP($BN17,$AX$6:$BL$175,BQ$5) -> 404.66966 | BR17: =VLOOKUP($BN17,$AX$6:$BL$175,BR$5) -> 419.18665 | BS17: =VLOOKUP($BN17,$AX$6:$BL$175,BS$5) -> 689.47147 | BT17: =VLOOKUP($BN17,$AX$6:$BL$175,BT$5) -> 676.356 | BU17: =VLOOKUP($BN17,$AX$6:$BL$175,BU$5) -> 605.42852 | BV17: =VLOOKUP($BN17,$AX$6:$BL$175,BV$5) -> 704.58556 | ... CB17: =VLOOKUP($BN17,$AX$6:$BL$175,CB$5) -> 686.26023
BM18: 253 | BN18: 41527 | BO18: =VLOOKUP($BN18,$AX$6:$BL$175,BO$5) -> 427.98358 | BP18: =VLOOKUP($BN18,$AX$6:$BL$175,BP$5) -> 420.81245 | BQ18: =VLOOKUP($BN18,$AX$6:$BL$175,BQ$5) -> 403.41662 | BR18: =VLOOKUP($BN18,$AX$6:$BL$175,BR$5) -> 414.43387 | BS18: =VLOOKUP($BN18,$AX$6:$BL$175,BS$5) -> 678.30766 | BT18: =VLOOKUP($BN18,$AX$6:$BL$175,BT$5) -> 662.00201 | BU18: =VLOOKUP($BN18,$AX$6:$BL$175,BU$5) -> 592.20141 | BV18: =VLOOKUP($BN18,$AX$6:$BL$175,BV$5) -> 691.30899 | ... CB18: =VLOOKUP($BN18,$AX$6:$BL$175,CB$5) -> 677.14302
Y19: 2013 | Z19: 157 | AA19: =DATE(Y19,1,Z19) -> 41431 | AB19: 10 | AC19: {=_xlfn.XLOOKUP(1,('2013 E Maize Soil VWC'!$C$2:$C$4000=$AA19)*('2013 E Maize Soil VWC'!$E$2:$E$4000=$AB19)*('2013 E Maize Soil VWC'!$F$2:$F$4000=AC$5),'2013 E Maize Soil VWC'!$G$2:$G$4000)} -> #N/A | AD19: {=_xlfn.XLOOKUP(1,('2013 E Maize Soil VWC'!$C$2:$C$4000=$AA19)*('2013 E Maize Soil VWC'!$E$2:$E$4000=$AB19)*('2013 E Maize Soil VWC'!$F$2:$F$4000=AD$5),'2013 E Maize Soil VWC'!$G$2:$G$4000)} -> #N/A | AE19: {=_xlfn.XLOOKUP(1,('2013 E Maize Soil VWC'!$C$2:$C$4000=$AA19)*('2013 E Maize Soil VWC'!$E$2:$E$4000=$AB19)*('2013 E Maize Soil VWC'!$F$2:$F$4000=AE$5),'2013 E Maize Soil VWC'!$G$2:$G$4000)} -> #N/A | AF19: {=_xlfn.XLOOKUP(1,('2013 E Maize Soil VWC'!$C$2:$C$4000=$AA19)*('2013 E Maize Soil VWC'!$E$2:$E$4000=$AB19)*('2013 E Maize Soil VWC'!$F$2:$F$4000=AF$5),'2013 E Maize Soil VWC'!$G$2:$G$4000)} -> #N/A | AG19: {=_xlfn.XLOOKUP(1,('2013 E Maize Soil VWC'!$C$2:$C$4000=$AA19)*('2013 E Maize Soil VWC'!$E$2:$E$4000=$AB19)*('2013 E Maize Soil VWC'!$F$2:$F$4000=AG$5),'2013 E Maize Soil VWC'!$G$2:$G$4000)} -> 0.29291756 | AH19: {=_xlfn.XLOOKUP(1,('2013 E Maize Soil VWC'!$C$2:$C$4000=$AA19)*('2013 E Maize Soil VWC'!$E$2:$E$4000=$AB19)*('2013 E Maize Soil VWC'!$F$2:$F$4000=AH$5),'2013 E Maize Soil VWC'!$G$2:$G$4000)} -> 0.27552782 | AI19: {=_xlfn.XLOOKUP(1,('2013 E Maize Soil VWC'!$C$2:$C$4000=$AA19)*('2013 E Maize Soil VWC'!$E$2:$E$4000=$AB19)*('2013 E Maize Soil VWC'!$F$2:$F$4000=AI$5),'2013 E Maize Soil VWC'!$G$2:$G$4000)} -> #N/A | AJ19: {=_xlfn.XLOOKUP(1,('2013 E Maize Soil VWC'!$C$2:$C$4000=$AA19)*('2013 E Maize Soil VWC'!$E$2:$E$4000=$AB19)*('2013 E Maize Soil VWC'!$F$2:$F$4000=AJ$5),'2013 E Maize Soil VWC'!$G$2:$G$4000)} -> #N/A | ... AV19: {=_xlfn.XLOOKUP(1,('2013 E Maize Soil VWC'!$C$2:$C$4000=$AA19)*('2013 E Maize Soil VWC'!$E$2:$E$4000=$AB19)*('2013 E Maize Soil VWC'!$F$2:$F$4000=AV$5),'2013 E Maize Soil VWC'!$G$2:$G$4000)} -> #N/A | AW19: =Z19 -> 157 | AX19: =AA19 -> 41431 | AY19: =1400*AVERAGE(AG19:AH25)+100*AVERAGE(AG26:AH26) -> 519.51406 | AZ19: =1400*AVERAGE(AC19:AF25,AI19:AL25)+100*AVERAGE(AC26:AF26,AI26:AL26) -> #N/A | BA19: =1400*AVERAGE(AQ19:AR25)+100*AVERAGE(AQ26:AR26) -> 508.71275 | BB19: =1400*AVERAGE(AM19:AP25,AS19:AV25)+100*AVERAGE(AM26:AP26,AS26:AV26) -> #N/A | BC19: =AVERAGE(AC19:AD30)*2400 -> #N/A | BD19: =AVERAGE(AE19:AF30)*2400 -> #N/A | BE19: =AVERAGE(AG19:AH28)*2000 -> 687.2538 | BF19: =AVERAGE(AI19:AJ30)*2400 -> #N/A | BG19: =AVERAGE(AK19:AL30)*2400 -> #N/A | BH19: =AVERAGE(AM19:AN30)*2400 -> #N/A | BI19: =AVERAGE(AO19:AP30)*2400 -> #N/A | BJ19: =AVERAGE(AQ19:AR28)*2000 -> 671.208 | BK19: =AVERAGE(AS19:AT30)*2400 -> #N/A | BL19: =AVERAGE(AU19:AV30)*2400 -> #N/A | BM19: 269 | BN19: 41543 | BO19: =VLOOKUP($BN19,$AX$6:$BL$175,BO$5) -> 436.86972 | BP19: =VLOOKUP($BN19,$AX$6:$BL$175,BP$5) -> 428.8739 | BQ19: =VLOOKUP($BN19,$AX$6:$BL$175,BQ$5) -> 416.18995 | BR19: =VLOOKUP($BN19,$AX$6:$BL$175,BR$5) -> 418.99131 | BS19: =VLOOKUP($BN19,$AX$6:$BL$175,BS$5) -> 681.0152 | BT19: =VLOOKUP($BN19,$AX$6:$BL$175,BT$5) -> 664.9376 | BU19: =VLOOKUP($BN19,$AX$6:$BL$175,BU$5) -> 600.65787 | BV19: =VLOOKUP($BN19,$AX$6:$BL$175,BV$5) -> 698.2462 | ... CB19: =VLOOKUP($BN19,$AX$6:$BL$175,CB$5) -> 676.135
AA20: =AA19 -> 41431 | AB20: =AB19+20 -> 30 | AC20: {=_xlfn.XLOOKUP(1,('2013 E Maize Soil VWC'!$C$2:$C$4000=$AA20)*('2013 E Maize Soil VWC'!$E$2:$E$4000=$AB20)*('2013 E Maize Soil VWC'!$F$2:$F$4000=AC$5),'2013 E Maize Soil VWC'!$G$2:$G$4000)} -> #N/A | AD20: {=_xlfn.XLOOKUP(1,('2013 E Maize Soil VWC'!$C$2:$C$4000=$AA20)*('2013 E Maize Soil VWC'!$E$2:$E$4000=$AB20)*('2013 E Maize Soil VWC'!$F$2:$F$4000=AD$5),'2013 E Maize Soil VWC'!$G$2:$G$4000)} -> #N/A | AE20: {=_xlfn.XLOOKUP(1,('2013 E Maize Soil VWC'!$C$2:$C$4000=$AA20)*('2013 E Maize Soil VWC'!$E$2:$E$4000=$AB20)*('2013 E Maize Soil VWC'!$F$2:$F$4000=AE$5),'2013 E Maize Soil VWC'!$G$2:$G$4000)} -> #N/A | AF20: {=_xlfn.XLOOKUP(1,('2013 E Maize Soil VWC'!$C$2:$C$4000=$AA20)*('2013 E Maize Soil VWC'!$E$2:$E$4000=$AB20)*('2013 E Maize Soil VWC'!$F$2:$F$4000=AF$5),'2013 E Maize Soil VWC'!$G$2:$G$4000)} -> #N/A | AG20: {=_xlfn.XLOOKUP(1,('2013 E Maize Soil VWC'!$C$2:$C$4000=$AA20)*('2013 E Maize Soil VWC'!$E$2:$E$4000=$AB20)*('2013 E Maize Soil VWC'!$F$2:$F$4000=AG$5),'2013 E Maize Soil VWC'!$G$2:$G$4000)} -> 0.36712889 | AH20: {=_xlfn.XLOOKUP(1,('2013 E Maize Soil VWC'!$C$2:$C$4000=$AA20)*('2013 E Maize Soil VWC'!$E$2:$E$4000=$AB20)*('2013 E Maize Soil VWC'!$F$2:$F$4000=AH$5),'2013 E Maize Soil VWC'!$G$2:$G$4000)} -> 0.35487236 | AI20: {=_xlfn.XLOOKUP(1,('2013 E Maize Soil VWC'!$C$2:$C$4000=$AA20)*('2013 E Maize Soil VWC'!$E$2:$E$4000=$AB20)*('2013 E Maize Soil VWC'!$F$2:$F$4000=AI$5),'2013 E Maize Soil VWC'!$G$2:$G$4000)} -> #N/A | AJ20: {=_xlfn.XLOOKUP(1,('2013 E Maize Soil VWC'!$C$2:$C$4000=$AA20)*('2013 E Maize Soil VWC'!$E$2:$E$4000=$AB20)*('2013 E Maize Soil VWC'!$F$2:$F$4000=AJ$5),'2013 E Maize Soil VWC'!$G$2:$G$4000)} -> #N/A | ... AV20: {=_xlfn.XLOOKUP(1,('2013 E Maize Soil VWC'!$C$2:$C$4000=$AA20)*('2013 E Maize Soil VWC'!$E$2:$E$4000=$AB20)*('2013 E Maize Soil VWC'!$F$2:$F$4000=AV$5),'2013 E Maize Soil VWC'!$G$2:$G$4000)} -> #N/A
